Workbook
Name __tst2: {#N/A,#N/A,TRUE,"カスタマイズ仕様書";#N/A,#N/A,TRUE,"Ｉ・Ｏ関連表(1)";#N/A,#N/A,TRUE,"Ｉ・Ｏ関連表(2)";#N/A,#N/A,TRUE,"Ｉ・Ｏ関連表(3)";#N/A,#N/A,TRUE,"レポート記述書";#N/A,#N/A,TRUE,"画面記述書"}
Name __tst2: {#N/A,#N/A,TRUE,"カスタマイズ仕様書";#N/A,#N/A,TRUE,"Ｉ・Ｏ関連表(1)";#N/A,#N/A,TRUE,"Ｉ・Ｏ関連表(2)";#N/A,#N/A,TRUE,"Ｉ・Ｏ関連表(3)";#N/A,#N/A,TRUE,"レポート記述書";#N/A,#N/A,TRUE,"画面記述書"}
Name __tst2: {#N/A,#N/A,TRUE,"カスタマイズ仕様書";#N/A,#N/A,TRUE,"Ｉ・Ｏ関連表(1)";#N/A,#N/A,TRUE,"Ｉ・Ｏ関連表(2)";#N/A,#N/A,TRUE,"Ｉ・Ｏ関連表(3)";#N/A,#N/A,TRUE,"レポート記述書";#N/A,#N/A,TRUE,"画面記述書"}
Name __tst2: {#N/A,#N/A,TRUE,"カスタマイズ仕様書";#N/A,#N/A,TRUE,"Ｉ・Ｏ関連表(1)";#N/A,#N/A,TRUE,"Ｉ・Ｏ関連表(2)";#N/A,#N/A,TRUE,"Ｉ・Ｏ関連表(3)";#N/A,#N/A,TRUE,"レポート記述書";#N/A,#N/A,TRUE,"画面記述書"}
Name __tst2: {#N/A,#N/A,TRUE,"カスタマイズ仕様書";#N/A,#N/A,TRUE,"Ｉ・Ｏ関連表(1)";#N/A,#N/A,TRUE,"Ｉ・Ｏ関連表(2)";#N/A,#N/A,TRUE,"Ｉ・Ｏ関連表(3)";#N/A,#N/A,TRUE,"レポート記述書";#N/A,#N/A,TRUE,"画面記述書"}
Name __tst2: {#N/A,#N/A,TRUE,"カスタマイズ仕様書";#N/A,#N/A,TRUE,"Ｉ・Ｏ関連表(1)";#N/A,#N/A,TRUE,"Ｉ・Ｏ関連表(2)";#N/A,#N/A,TRUE,"Ｉ・Ｏ関連表(3)";#N/A,#N/A,TRUE,"レポート記述書";#N/A,#N/A,TRUE,"画面記述書"}
Name A4縦_フッタロゴなし: {#N/A,#N/A,TRUE,"カスタマイズ仕様書";#N/A,#N/A,TRUE,"Ｉ・Ｏ関連表(1)";#N/A,#N/A,TRUE,"Ｉ・Ｏ関連表(2)";#N/A,#N/A,TRUE,"Ｉ・Ｏ関連表(3)";#N/A,#N/A,TRUE,"レポート記述書";#N/A,#N/A,TRUE,"画面記述書"}
Name A4縦_フッタロゴなし: {#N/A,#N/A,TRUE,"カスタマイズ仕様書";#N/A,#N/A,TRUE,"Ｉ・Ｏ関連表(1)";#N/A,#N/A,TRUE,"Ｉ・Ｏ関連表(2)";#N/A,#N/A,TRUE,"Ｉ・Ｏ関連表(3)";#N/A,#N/A,TRUE,"レポート記述書";#N/A,#N/A,TRUE,"画面記述書"}
Name A4縦_フッタロゴなし: {#N/A,#N/A,TRUE,"カスタマイズ仕様書";#N/A,#N/A,TRUE,"Ｉ・Ｏ関連表(1)";#N/A,#N/A,TRUE,"Ｉ・Ｏ関連表(2)";#N/A,#N/A,TRUE,"Ｉ・Ｏ関連表(3)";#N/A,#N/A,TRUE,"レポート記述書";#N/A,#N/A,TRUE,"画面記述書"}
Name A4縦_フッタロゴなし: {#N/A,#N/A,TRUE,"カスタマイズ仕様書";#N/A,#N/A,TRUE,"Ｉ・Ｏ関連表(1)";#N/A,#N/A,TRUE,"Ｉ・Ｏ関連表(2)";#N/A,#N/A,TRUE,"Ｉ・Ｏ関連表(3)";#N/A,#N/A,TRUE,"レポート記述書";#N/A,#N/A,TRUE,"画面記述書"}
Name A4縦_フッタロゴなし: {#N/A,#N/A,TRUE,"カスタマイズ仕様書";#N/A,#N/A,TRUE,"Ｉ・Ｏ関連表(1)";#N/A,#N/A,TRUE,"Ｉ・Ｏ関連表(2)";#N/A,#N/A,TRUE,"Ｉ・Ｏ関連表(3)";#N/A,#N/A,TRUE,"レポート記述書";#N/A,#N/A,TRUE,"画面記述書"}
Name A4縦_フッタロゴなし: {#N/A,#N/A,TRUE,"カスタマイズ仕様書";#N/A,#N/A,TRUE,"Ｉ・Ｏ関連表(1)";#N/A,#N/A,TRUE,"Ｉ・Ｏ関連表(2)";#N/A,#N/A,TRUE,"Ｉ・Ｏ関連表(3)";#N/A,#N/A,TRUE,"レポート記述書";#N/A,#N/A,TRUE,"画面記述書"}
Name A4縦_雛形フッタロゴなし: {#N/A,#N/A,TRUE,"カスタマイズ仕様書";#N/A,#N/A,TRUE,"Ｉ・Ｏ関連表(1)";#N/A,#N/A,TRUE,"Ｉ・Ｏ関連表(2)";#N/A,#N/A,TRUE,"Ｉ・Ｏ関連表(3)";#N/A,#N/A,TRUE,"レポート記述書";#N/A,#N/A,TRUE,"画面記述書"}
Name A4縦_雛形フッタロゴなし: {#N/A,#N/A,TRUE,"カスタマイズ仕様書";#N/A,#N/A,TRUE,"Ｉ・Ｏ関連表(1)";#N/A,#N/A,TRUE,"Ｉ・Ｏ関連表(2)";#N/A,#N/A,TRUE,"Ｉ・Ｏ関連表(3)";#N/A,#N/A,TRUE,"レポート記述書";#N/A,#N/A,TRUE,"画面記述書"}
Name A4縦_雛形フッタロゴなし: {#N/A,#N/A,TRUE,"カスタマイズ仕様書";#N/A,#N/A,TRUE,"Ｉ・Ｏ関連表(1)";#N/A,#N/A,TRUE,"Ｉ・Ｏ関連表(2)";#N/A,#N/A,TRUE,"Ｉ・Ｏ関連表(3)";#N/A,#N/A,TRUE,"レポート記述書";#N/A,#N/A,TRUE,"画面記述書"}
Name A4縦_雛形フッタロゴなし: {#N/A,#N/A,TRUE,"カスタマイズ仕様書";#N/A,#N/A,TRUE,"Ｉ・Ｏ関連表(1)";#N/A,#N/A,TRUE,"Ｉ・Ｏ関連表(2)";#N/A,#N/A,TRUE,"Ｉ・Ｏ関連表(3)";#N/A,#N/A,TRUE,"レポート記述書";#N/A,#N/A,TRUE,"画面記述書"}
Name A4縦_雛形フッタロゴなし: {#N/A,#N/A,TRUE,"カスタマイズ仕様書";#N/A,#N/A,TRUE,"Ｉ・Ｏ関連表(1)";#N/A,#N/A,TRUE,"Ｉ・Ｏ関連表(2)";#N/A,#N/A,TRUE,"Ｉ・Ｏ関連表(3)";#N/A,#N/A,TRUE,"レポート記述書";#N/A,#N/A,TRUE,"画面記述書"}
Name A4縦_雛形フッタロゴなし: {#N/A,#N/A,TRUE,"カスタマイズ仕様書";#N/A,#N/A,TRUE,"Ｉ・Ｏ関連表(1)";#N/A,#N/A,TRUE,"Ｉ・Ｏ関連表(2)";#N/A,#N/A,TRUE,"Ｉ・Ｏ関連表(3)";#N/A,#N/A,TRUE,"レポート記述書";#N/A,#N/A,TRUE,"画面記述書"}
Name aaaaa: {#N/A,#N/A,TRUE,"カスタマイズ仕様書";#N/A,#N/A,TRUE,"Ｉ・Ｏ関連表(1)";#N/A,#N/A,TRUE,"Ｉ・Ｏ関連表(2)";#N/A,#N/A,TRUE,"Ｉ・Ｏ関連表(3)";#N/A,#N/A,TRUE,"レポート記述書";#N/A,#N/A,TRUE,"画面記述書"}
Name aaaaa: {#N/A,#N/A,TRUE,"カスタマイズ仕様書";#N/A,#N/A,TRUE,"Ｉ・Ｏ関連表(1)";#N/A,#N/A,TRUE,"Ｉ・Ｏ関連表(2)";#N/A,#N/A,TRUE,"Ｉ・Ｏ関連表(3)";#N/A,#N/A,TRUE,"レポート記述書";#N/A,#N/A,TRUE,"画面記述書"}
Name aaaaa: {#N/A,#N/A,TRUE,"カスタマイズ仕様書";#N/A,#N/A,TRUE,"Ｉ・Ｏ関連表(1)";#N/A,#N/A,TRUE,"Ｉ・Ｏ関連表(2)";#N/A,#N/A,TRUE,"Ｉ・Ｏ関連表(3)";#N/A,#N/A,TRUE,"レポート記述書";#N/A,#N/A,TRUE,"画面記述書"}
Name aaaaa: {#N/A,#N/A,TRUE,"カスタマイズ仕様書";#N/A,#N/A,TRUE,"Ｉ・Ｏ関連表(1)";#N/A,#N/A,TRUE,"Ｉ・Ｏ関連表(2)";#N/A,#N/A,TRUE,"Ｉ・Ｏ関連表(3)";#N/A,#N/A,TRUE,"レポート記述書";#N/A,#N/A,TRUE,"画面記述書"}
Name aaaaa: {#N/A,#N/A,TRUE,"カスタマイズ仕様書";#N/A,#N/A,TRUE,"Ｉ・Ｏ関連表(1)";#N/A,#N/A,TRUE,"Ｉ・Ｏ関連表(2)";#N/A,#N/A,TRUE,"Ｉ・Ｏ関連表(3)";#N/A,#N/A,TRUE,"レポート記述書";#N/A,#N/A,TRUE,"画面記述書"}
Name aaaaa: {#N/A,#N/A,TRUE,"カスタマイズ仕様書";#N/A,#N/A,TRUE,"Ｉ・Ｏ関連表(1)";#N/A,#N/A,TRUE,"Ｉ・Ｏ関連表(2)";#N/A,#N/A,TRUE,"Ｉ・Ｏ関連表(3)";#N/A,#N/A,TRUE,"レポート記述書";#N/A,#N/A,TRUE,"画面記述書"}
Name BIS作成種類: OFFSET([1]設定!$B$2,,,COUNTA([1]設定!$B:$B)-1)
Name BIS作成種類: OFFSET([2]設定!$B$2,,,COUNTA([2]設定!$B:$B)-1)
Name BIS作成種類: OFFSET([1]設定!$B$2,,,COUNTA([1]設定!$B:$B)-1)
Name BIS作成種類: OFFSET([2]設定!$B$2,,,COUNTA([2]設定!$B:$B)-1)
Name BIS作成種類: OFFSET([2]設定!$B$2,,,COUNTA([2]設定!$B:$B)-1)
Name BIS作成種類: OFFSET(Cài đặt!$B$2,,,COUNTA(Cài đặt!$B:$B)-1)
Name ｇｇｇｇ: {#N/A,#N/A,TRUE,"カスタマイズ仕様書";#N/A,#N/A,TRUE,"Ｉ・Ｏ関連表(1)";#N/A,#N/A,TRUE,"Ｉ・Ｏ関連表(2)";#N/A,#N/A,TRUE,"Ｉ・Ｏ関連表(3)";#N/A,#N/A,TRUE,"レポート記述書";#N/A,#N/A,TRUE,"画面記述書"}
Name HTML1_1: "[帳票管理資料.xls]集計表!$A$1:$R$32"
Name HTML1_10: ""
Name HTML1_11: 1
Name HTML1_12: "C:\My Documents\MyHTML.htm"
Name HTML1_2: 1
Name HTML1_3: "帳票管理資料.xls"
Name HTML1_4: "集計表"
Name HTML1_5: ""
Name HTML1_6: -4146
Name HTML1_7: -4146
Name HTML1_8: "97/07/14"
Name HTML1_9: "お客様各位"
Name HTMLCount: 1
Name s: {#N/A,#N/A,TRUE,"カスタマイズ仕様書";#N/A,#N/A,TRUE,"Ｉ・Ｏ関連表(1)";#N/A,#N/A,TRUE,"Ｉ・Ｏ関連表(2)";#N/A,#N/A,TRUE,"Ｉ・Ｏ関連表(3)";#N/A,#N/A,TRUE,"レポート記述書";#N/A,#N/A,TRUE,"画面記述書"}
Name s: {#N/A,#N/A,TRUE,"カスタマイズ仕様書";#N/A,#N/A,TRUE,"Ｉ・Ｏ関連表(1)";#N/A,#N/A,TRUE,"Ｉ・Ｏ関連表(2)";#N/A,#N/A,TRUE,"Ｉ・Ｏ関連表(3)";#N/A,#N/A,TRUE,"レポート記述書";#N/A,#N/A,TRUE,"画面記述書"}
Name s: {#N/A,#N/A,TRUE,"カスタマイズ仕様書";#N/A,#N/A,TRUE,"Ｉ・Ｏ関連表(1)";#N/A,#N/A,TRUE,"Ｉ・Ｏ関連表(2)";#N/A,#N/A,TRUE,"Ｉ・Ｏ関連表(3)";#N/A,#N/A,TRUE,"レポート記述書";#N/A,#N/A,TRUE,"画面記述書"}
Name s: {#N/A,#N/A,TRUE,"カスタマイズ仕様書";#N/A,#N/A,TRUE,"Ｉ・Ｏ関連表(1)";#N/A,#N/A,TRUE,"Ｉ・Ｏ関連表(2)";#N/A,#N/A,TRUE,"Ｉ・Ｏ関連表(3)";#N/A,#N/A,TRUE,"レポート記述書";#N/A,#N/A,TRUE,"画面記述書"}
Name s: {#N/A,#N/A,TRUE,"カスタマイズ仕様書";#N/A,#N/A,TRUE,"Ｉ・Ｏ関連表(1)";#N/A,#N/A,TRUE,"Ｉ・Ｏ関連表(2)";#N/A,#N/A,TRUE,"Ｉ・Ｏ関連表(3)";#N/A,#N/A,TRUE,"レポート記述書";#N/A,#N/A,TRUE,"画面記述書"}
Name s: {#N/A,#N/A,TRUE,"カスタマイズ仕様書";#N/A,#N/A,TRUE,"Ｉ・Ｏ関連表(1)";#N/A,#N/A,TRUE,"Ｉ・Ｏ関連表(2)";#N/A,#N/A,TRUE,"Ｉ・Ｏ関連表(3)";#N/A,#N/A,TRUE,"レポート記述書";#N/A,#N/A,TRUE,"画面記述書"}
Name ss: {#N/A,#N/A,TRUE,"カスタマイズ仕様書";#N/A,#N/A,TRUE,"Ｉ・Ｏ関連表(1)";#N/A,#N/A,TRUE,"Ｉ・Ｏ関連表(2)";#N/A,#N/A,TRUE,"Ｉ・Ｏ関連表(3)";#N/A,#N/A,TRUE,"レポート記述書";#N/A,#N/A,TRUE,"画面記述書"}
Name ss: {#N/A,#N/A,TRUE,"カスタマイズ仕様書";#N/A,#N/A,TRUE,"Ｉ・Ｏ関連表(1)";#N/A,#N/A,TRUE,"Ｉ・Ｏ関連表(2)";#N/A,#N/A,TRUE,"Ｉ・Ｏ関連表(3)";#N/A,#N/A,TRUE,"レポート記述書";#N/A,#N/A,TRUE,"画面記述書"}
Name ss: {#N/A,#N/A,TRUE,"カスタマイズ仕様書";#N/A,#N/A,TRUE,"Ｉ・Ｏ関連表(1)";#N/A,#N/A,TRUE,"Ｉ・Ｏ関連表(2)";#N/A,#N/A,TRUE,"Ｉ・Ｏ関連表(3)";#N/A,#N/A,TRUE,"レポート記述書";#N/A,#N/A,TRUE,"画面記述書"}
Name ss: {#N/A,#N/A,TRUE,"カスタマイズ仕様書";#N/A,#N/A,TRUE,"Ｉ・Ｏ関連表(1)";#N/A,#N/A,TRUE,"Ｉ・Ｏ関連表(2)";#N/A,#N/A,TRUE,"Ｉ・Ｏ関連表(3)";#N/A,#N/A,TRUE,"レポート記述書";#N/A,#N/A,TRUE,"画面記述書"}
Name ss: {#N/A,#N/A,TRUE,"カスタマイズ仕様書";#N/A,#N/A,TRUE,"Ｉ・Ｏ関連表(1)";#N/A,#N/A,TRUE,"Ｉ・Ｏ関連表(2)";#N/A,#N/A,TRUE,"Ｉ・Ｏ関連表(3)";#N/A,#N/A,TRUE,"レポート記述書";#N/A,#N/A,TRUE,"画面記述書"}
Name ss: {#N/A,#N/A,TRUE,"カスタマイズ仕様書";#N/A,#N/A,TRUE,"Ｉ・Ｏ関連表(1)";#N/A,#N/A,TRUE,"Ｉ・Ｏ関連表(2)";#N/A,#N/A,TRUE,"Ｉ・Ｏ関連表(3)";#N/A,#N/A,TRUE,"レポート記述書";#N/A,#N/A,TRUE,"画面記述書"}
Name ｔｓｔ: {#N/A,#N/A,TRUE,"カスタマイズ仕様書";#N/A,#N/A,TRUE,"Ｉ・Ｏ関連表(1)";#N/A,#N/A,TRUE,"Ｉ・Ｏ関連表(2)";#N/A,#N/A,TRUE,"Ｉ・Ｏ関連表(3)";#N/A,#N/A,TRUE,"レポート記述書";#N/A,#N/A,TRUE,"画面記述書"}
Name ｔｓｔ: {#N/A,#N/A,TRUE,"カスタマイズ仕様書";#N/A,#N/A,TRUE,"Ｉ・Ｏ関連表(1)";#N/A,#N/A,TRUE,"Ｉ・Ｏ関連表(2)";#N/A,#N/A,TRUE,"Ｉ・Ｏ関連表(3)";#N/A,#N/A,TRUE,"レポート記述書";#N/A,#N/A,TRUE,"画面記述書"}
Name ｔｓｔ: {#N/A,#N/A,TRUE,"カスタマイズ仕様書";#N/A,#N/A,TRUE,"Ｉ・Ｏ関連表(1)";#N/A,#N/A,TRUE,"Ｉ・Ｏ関連表(2)";#N/A,#N/A,TRUE,"Ｉ・Ｏ関連表(3)";#N/A,#N/A,TRUE,"レポート記述書";#N/A,#N/A,TRUE,"画面記述書"}
Name ｔｓｔ: {#N/A,#N/A,TRUE,"カスタマイズ仕様書";#N/A,#N/A,TRUE,"Ｉ・Ｏ関連表(1)";#N/A,#N/A,TRUE,"Ｉ・Ｏ関連表(2)";#N/A,#N/A,TRUE,"Ｉ・Ｏ関連表(3)";#N/A,#N/A,TRUE,"レポート記述書";#N/A,#N/A,TRUE,"画面記述書"}

Sheet Header
A1: ↓ Nhập thông tin gốc ↓ ※ Ẩn khi in
A2: Tên dự án | I2: Tên hệ thống (ID) | P2: Phân loại | V2: Tên nghiệp vụ (ID) | AB2: Tên (ID) | AJ2: Ver． | AL2: Người tạo | AP2: Ngày tạo | AS2: Người cập nhật | AW2: Ngày cập nhật
A3: Cổng thông tin nhân viên | I3: Cổng thông tin HROne | P3: Tài liệu thiết kế màn hình | V3: Đơn yêu cầu | AB3: Đơn xin bắt đầu trợ cấp bảo hiểm thất nghiệp_Người cao tuổi | AJ3: ='Trang bìa'!AF31 -> 1.1.4 | AL3: ACF | AP3: 45163 | AS3: =OFFSET('Lịch sử cập nhật'!N6,COUNTA('Lịch sử cập nhật'!N6:N65531)-1,0) -> ACF | AW3: =OFFSET('Lịch sử cập nhật'!H6,COUNTA('Lịch sử cập nhật'!H6:H65531)-1,0) -> 45957

Sheet Trang bìa
O3: =Header!A3
O4: =Header!I3
O7: Tài liệu thiết kế cơ bản
O10: =Header!AB3
Z21: Ngày tạo | AF21: =Header!AP3 -> 45163
Z23: Ngày cập nhật cuối cùng | AF23: =Header!AW3 -> 45957
Z25: Người cập nhật cuối cùng | AF25: =Header!AS3 -> ACF
Z27: Ngày xem xét/phê duyệt | AF27: =OFFSET('Lịch sử cập nhật'!AT6,COUNTA('Lịch sử cập nhật'!AT6:AT65531)-1,0)
Z29: Người xem xét/phê duyệt | AF29: =OFFSET('Lịch sử cập nhật'!AY6,COUNTA('Lịch sử cập nhật'!AY6:AY65531)-1,0)
Z31: Phiên bản | AF31: =OFFSET('Lịch sử cập nhật'!C6,COUNTA('Lịch sử cập nhật'!C6:C65531)-1,0) -> 1.1.4

Sheet Lịch sử cập nhật
A5: No. | C5: Ver. | H5: Ngày tạo/thay đổi | N5: Người tạo/thay đổi | T5: Nội dung tạo/thay đổi | AT5: Ngày xem xét/phê duyệt | AY5: Người xem xét/phê duyệt
A6: 1 | C6: 1.0.0 | H6: 45163 | N6: ACF | T6: Tạo mới
A7: 2 | C7: 1.0.1 | H7: 45218 | N7: ACF | T7: Thêm hình ảnh màn hình di động
A8: 3 | C8: 1.0.2 | H8: 45243 | N8: ACF | T8: Điều khiển theo trạng thái Sửa đổi điều khiển Trạng thái = Đang chờ yêu cầu thông báo
A9: 4 | C9: 1.0.3 | H9: 45259 | N9: ACF | T9: Sửa đổi cuối cùng việc điều khiển hiển thị tệp đính kèm
A10: 5 | C10: 1.0.4 | H10: 45264 | N10: ACF | T10: Chỉnh sửa kiểm soát hiển thị đồng ý đăng ký tiền lương Sheet kiểm soát hiển thị theo mục lựa chọn
A11: 6 | C11: 1.0.5 | H11: 45265 | N11: ACF | T11: Thay đổi kiểm soát thời điểm hiển thị tài liệu đính kèm Sheet hiển thị theo mục lựa chọn
A12: 7 | C12: 1.0.6 | H12: 45265 | N12: ACF | T12: Kiểm soát hiển thị thông báo hướng dẫn riêng và tệp đính kèm cho người phụ trách
A13: 8 | C13: 1.1.0 | H13: 45595 | N13: ACF | T13: Hỗ trợ bộ kit
A14: 9 | C14: 1.1.2 | H14: 45713 | N14: ACF | T14: Sửa lỗi chỉ định
A15: 10 | C15: 1.1.3 | H15: 45772 | N15: ACF | T15: Sửa lỗi chỉ định
A16: 11 | C16: 1.1.4 | H16: 45957 | N16: ACF | T16: Sửa lỗi chỉ định

Sheet Tổng quan chuyển tiếp màn hình
A5: 【Tổng quan】

Sheet ★Mẫu gọi màn hình
B5: ■ Mẫu gọi màn hình
B6: Mẫu gọi của màn hình này như sau
B8: Số thứ tự | C8: Màn hình gọi | D8: Sự kiện gọi | E8: Hiển thị màn hình | F8: Người dùng đăng nhập | G8: Điều kiện gọi
B9: 1 | C9: Xem trước thông báo hướng dẫn | D9: Liên kết đến đơn yêu cầu | E9: Modal | F9: Người phụ trách HROne/HRP | G9: Không có
B10: 2 | C10: Tìm kiếm yêu cầu/thông báo dành cho người phụ trách HROne/HRP | D10: Nhấp vào liên kết tiêu đề | E10: Popup | F10: Người phụ trách HROne/HRP | G10: Không có
B11: 3 | C11: Chi tiết thông báo hướng dẫn | D11: Liên kết yêu cầu thông báo | E11: Chuyển màn hình | F11: Nhân viên khách hàng | G11: Trạng thái của yêu cầu thông báo là 「Đang yêu cầu ・ chờ thông báo」
B12: 4 | C12: Chi tiết thông báo hướng dẫn | D12: Liên kết yêu cầu thông báo | E12: Chuyển màn hình | F12: Nhân viên khách hàng | G12: Trạng thái của yêu cầu thông báo là 「Yêu cầu ・đang thông báo」
B13: 5 | C13: Chi tiết thông báo hướng dẫn | D13: Liên kết yêu cầu thông báo | E13: Chuyển màn hình | F13: Nhân viên khách hàng | G13: Trạng thái yêu cầu thông báo là 「Đã tiếp nhận」, 「Đang xử lý」, 「Hoàn thành」
B14: 6 | C14: Danh sách yêu cầu và thông báo _ dành cho nhân viên khách hàng | D14: Nhấp hàng | E14: Chuyển màn hình | F14: Nhân viên khách hàng | G14: Trạng thái của yêu cầu thông báo là 「Đang yêu cầu ・ chờ thông báo」
B15: 7 | C15: Danh sách yêu cầu và thông báo _ dành cho nhân viên khách hàng | D15: Nhấp hàng | E15: Chuyển màn hình | F15: Nhân viên khách hàng | G15: Trạng thái của yêu cầu thông báo là 「Yêu cầu ・đang thông báo」
B16: 8 | C16: Danh sách yêu cầu và thông báo _ dành cho nhân viên khách hàng | D16: Nhấp hàng | E16: Chuyển màn hình | F16: Nhân viên khách hàng | G16: Trạng thái yêu cầu thông báo là 「Đã tiếp nhận」, 「Đang xử lý」, 「Hoàn thành」

Sheet Bố cục màn hình_Đơn xin trợ cấp
A5: ◆ Màn hình khi hiển thị ban đầu
A6: 【Màn hình ngoài điện thoại thông minh】 | BD6: 【Màn hình điện thoại thông minh】

Sheet ★ Định nghĩa hạng mục màn hình_
A5: No. | B5: Tên mục | C5: ID mục (không bao gồm ID loại) | D5: Loại | E5: Khái quát xử lý | F5: Nội dung gợi ý | G5: ID nhãn | H5: Thuộc tính | I5: Số chữ số | J5: Định dạng | K5: Giá trị mặc định (Khi đăng ký mới) | L5: Kiểm tra nhập liệu | O5: Căn lề văn bản | P5: Phân trang | Q5: Cơ sở dữ liệu | S5: Ghi chú
L6: Bắt buộc | M6: Kiểm tra định dạng | N6: Ràng buộc nhập liệu | Q6: Tên bảng | R6: Tên mục bảng
A7: =ROW()-6 -> 1 | B7: Quay lại | F7: ー | J7: ー | K7: ー | L7: ー | M7: ー | N7: ー
A8: =ROW()-6 -> 2 | B8: Khu vực hiển thị chung cho đơn yêu cầu/khai báo | E8: ー | F8: ー | J8: ー | K8: ー | L8: ー | M8: ー | N8: ー | S8: Tham chiếu 【Tài liệu thiết kế cơ bản】 Thiết kế màn hình_Chung cho yêu cầu và thông báo
A9: 5 | B9: Khu vực thông tin nhân viên | F9: ー | J9: ー | K9: ー | L9: ー | M9: ー | N9: ー
A10: 6 | B10: Tên công ty | E10: Hiển thị tên công ty mà nhân viên trực thuộc | F10: ー | J10: ー | K10: ー | L10: ー | M10: ー | N10: ー
A11: 7 | B11: Mã số nhân viên | E11: Hiển thị mã số nhân viên | F11: ー | J11: ー | K11: ー | L11: ー | M11: ー | N11: ー
A12: 8 | B12: Tên nhân viên | E12: Hiển thị tên nhân viên | F12: ー | J12: Họ tên_Họ (Kanji) ＋ ” ” ＋ Họ tên_Tên (Kanji) | K12: ー | L12: ー | M12: ー | N12: ー
A13: 9 | B13: Mã cơ sở bảo hiểm xã hội | E13: Hiển thị mã cơ sở Sharo-mu của nhân viên (Số cơ sở dùng cho Sharo-mu trong Master thuộc tính người dùng) | F13: ー | J13: ー | K13: ー | L13: ー | M13: ー | N13: ー
A14: 10 | B14: Khu vực có/không có số My Number | F14: ー | J14: ー | K14: ー | L14: ー | M14: ー | N14: ー
A15: 11 | B15: Số My Number | D15: Nút chọn (Radio button) | F15: ー | J15: ー | K15: ー | L15: ー | M15: ー | N15: ー
A16: 12 | B16: Khu vực ý chí đăng ký | F16: ー | J16: ー | K16: ー | L16: ー | M16: ー | N16: ー
A17: 13 | B17: Ý định đăng ký trợ cấp | D17: Nút chọn (Radio button) | F17: ー | J17: ー | K17: ー | L17: 〇 | M17: ー | N17: ー
A18: 14 | B18: Đồng ý đăng ký tiền lương | D18: Hộp kiểm | F18: ー | J18: ー | K18: ー | L18: △ | M18: ー | N18: ー
A19: 15 | B19: Khu vực thông tin tài khoản nhận trợ cấp | F19: ー | J19: ー | K19: ー | L19: ー | M19: ー | N19: ー
A20: 16 | B20: Phân loại tổ chức tài chính | D20: Nút chọn (Radio button) | L20: △ | M20: ー | N20: ー
A21: 17 | B21: Ký hiệu | D21: Hộp văn bản | F21: Ví dụ) 12345 | J21: 5 chữ số nửa chiều rộng | L21: △ | M21: ○ | N21: ー | S21: Tham chiếu kiểm soát hiển thị theo mục lựa chọn
A22: 18 | B22: Số | D22: Hộp văn bản | F22: Ví dụ) 12345678 | J22: 8 chữ số nửa chiều rộng | L22: △ | M22: ○ | N22: ー | S22: Tham chiếu kiểm soát hiển thị theo mục lựa chọn
A23: 19 | B23: Mã tổ chức tài chính | D23: Hộp văn bản | F23: Ví dụ) 1234 | J23: 4 chữ số nửa chiều rộng | L23: △ | M23: ○ | N23: ー | S23: Tham chiếu kiểm soát hiển thị theo mục lựa chọn
A24: 20 | B24: Tên tổ chức tài chính | D24: Hộp văn bản | E24: ー | F24: Ví dụ) Ngân hàng ●● | J24: ー | L24: △ | M24: ー | N24: ー | S24: Tham chiếu kiểm soát hiển thị theo mục lựa chọn
A25: 21 | B25: Mã chi nhánh | D25: Hộp văn bản | F25: Ví dụ) 123 | J25: 3 chữ số nửa chiều rộng | L25: △ | M25: ○ | N25: ー | S25: Tham chiếu kiểm soát hiển thị theo mục lựa chọn
A26: 22 | B26: Tên trụ sở chính/chi nhánh | D26: Hộp văn bản | E26: ー | F26: Ví dụ) Chi nhánh ●● | J26: ー | L26: △ | M26: ー | N26: ー | S26: Tham chiếu kiểm soát hiển thị theo mục lựa chọn
A27: 23 | B27: Số tài khoản | D27: Hộp văn bản | F27: Ví dụ) 1234567 | J27: 7 chữ số nửa chiều rộng | L27: △ | M27: ○ | N27: ー | S27: Tham chiếu kiểm soát hiển thị theo mục lựa chọn
A28: 24 | B28: Khu vực tài liệu đính kèm | L28: ー | M28: ー | N28: ー
A29: 25 | B29: Tài liệu đính kèm | D29: Đính kèm tệp | E29: ※Đối với di động, có thể khởi động camera điện thoại và đính kèm hình ảnh đã chụp | L29: △ | M29: ー | N29: ー | S29: Tham chiếu kiểm soát hiển thị theo mục lựa chọn
A30: 26 | B30: Khu vực dành cho người phụ trách nội bộ sử dụng | L30: ー | M30: ー | N30: ー
A31: 27 | B31: Cột dành cho người phụ trách nội bộ | D31: Vùng văn bản | L31: ー | M31: ー | N31: ー
A32: 28 | B32: Cờ vô hiệu hóa | D32: Hộp kiểm | L32: ー | M32: ー | N32: ー
A33: 29 | B33: Lưu tạm thời | D33: Nút bấm | E33: Lưu tạm thời nội dung nhập | L33: ー | M33: ー | N33: ー
A34: 30 | B34: Yêu cầu / Thông báo | D34: Nút bấm | E34: Xác nhận nhập và cập nhật trạng thái thành Đang yêu cầu/Thông báo | L34: ー | M34: ー | N34: ー
A35: 31 | B35: Thu hồi | D35: Nút bấm | E35: Thu hồi các vụ việc đang trong quá trình yêu cầu thông báo và đưa trạng thái trở lại thành Chờ yêu cầu・thông báo | L35: ー | M35: ー | N35: ー
A36: 32 | B36: Đăng ký | D36: Nút bấm | E36: Đăng ký nội dung nhập
A37: 33 | B37: Lịch sử xử lý | D37: Nút bấm | E37: Hiển thị lịch sử xử lý dưới dạng popup
A48: 【Bổ sung】

Sheet ★ Tổng quan sự kiện
A5: No. | B5: Hạng mục | C5: Sự kiện | D5: Khái quát xử lý
A7: =ROW()-6 -> 1 | B7: Màn hình | C7: Hiển thị ban đầu | D7: ① Tìm kiếm đơn đăng ký Bảo hiểm thất nghiệp_Trợ cấp tuổi già theo Số thông báo yêu cầu. Nếu dữ liệu tồn tại, thiết lập dữ liệu vào các mục trên màn hình. ② Tùy theo màn hình gọi và điều kiện gọi, thực hiện kiểm soát hiển thị các mục trên màn hình theo "Kiểm soát hiển thị màn hình theo mẫu gọi". ③ Tùy theo quyền hạn của người dùng đăng nhập, thực hiện kiểm soát khả năng cập nhật màn hình theo "Kiểm soát cập nhật theo quyền hạn/trạng thái" trong sheet "Kiểm soát theo trạng thái", và thực hiện kiểm soát kích hoạt/vô hiệu hóa nút bấm theo "Kiểm soát nút xử lý theo trạng thái". ④ Thực hiện kiểm soát hiển thị các mục trên màn hình theo "Kiểm soát hiển thị mục màn hình" trong sheet "Kiểm soát hiển thị theo mục chọn".
A8: =ROW()-6 -> 2 | B8: Ý định đăng ký | C8: Chọn | D8: Trường hợp chọn "Đồng ý với nội dung dưới đây và đăng ký" Hiển thị Phân loại tổ chức tài chính Trường hợp chọn "Không đăng ký" Hiển thị Đồng ý đăng ký tiền lương Xóa tất cả các mục trong vùng thông tin tài khoản nhận trợ cấp và ẩn đi
A9: =ROW()-6 -> 3 | B9: Phân loại tổ chức tài chính | C9: Chọn | D9: Trường hợp chọn 「Ngân hàng Yucho」 Hiển thị Ký hiệu-Số Trường hợp My Number = Không có: Hiển thị tệp đính kèm Xóa giá trị nhập của Mã định danh tổ chức tài chính, Tên tổ chức tài chính, Mã chi nhánh, Tên trụ sở/chi nhánh, Số tài khoản Trường hợp chọn 「Tổ chức tài chính khác」 Hiển thị Mã định danh tổ chức tài chính, Tên tổ chức tài chính, Mã chi nhánh, Tên trụ sở/chi nhánh, Số tài khoản Trường hợp My Number = Không có: Hiển thị tệp đính kèm Xóa giá trị nhập của Ký hiệu-Số
A10: =ROW()-6 -> 4 | B10: Lưu tạm thời | C10: Click | D10: Lưu tạm thời nội dung nhập (Không cần kiểm tra bắt buộc) Trạng thái = Đang chờ yêu cầu thông báo Thêm vào lịch sử xử lý
A11: =ROW()-6 -> 5 | B11: Yêu cầu / Thông báo | C11: Click | D11: Thực hiện kiểm tra nhập liệu theo mục 「Kiểm tra nhập liệu」 của sheet 「Điều khiển hiển thị theo mục chọn」, sau đó đăng ký nội dung nhập Trạng thái = Đang yêu cầu thông báo Thêm vào lịch sử xử lý
A12: =ROW()-6 -> 6 | B12: Thu hồi | C12: Click | D12: Cập nhật trạng thái thành Đang chờ yêu cầu thông báo Thêm vào lịch sử xử lý
A13: =ROW()-6 -> 7 | B13: Đăng ký | C13: Click | D13: Cập nhật cột dành cho người phụ trách nội bộ, cờ vô hiệu hóa Thêm vào lịch sử xử lý
A14: =ROW()-6 -> 8 | B14: Lịch sử xử lý | C14: Click | D14: Hiển thị màn hình lịch sử xử lý dưới dạng pop-up
A15: =ROW()-6 -> 9
A16: =ROW()-6 -> 10
A17: =ROW()-6 -> 11
A18: =ROW()-6 -> 12
A19: =ROW()-6 -> 13
A20: =ROW()-6 -> 14
A21: =ROW()-6 -> 15
A22: =ROW()-6 -> 16
A23: =ROW()-6 -> 17
A24: =ROW()-6 -> 18
A25: =ROW()-6 -> 19
A26: =ROW()-6 -> 20
... A41: =ROW()-6 -> 35
A42: 37
A43: 【Bổ sung】

Sheet ★ Kiểm soát hiển thị màn hình t
A5: ■ Điều khiển hiển thị màn hình bởi bên gọi như sau
A7: No. | B7: Tên mục | C7: Người phụ trách HROne/HRP | E7: Nhân viên khách hàng | K7: Ghi chú
C8: Thông báo hướng dẫn Xem trước | D8: Tìm kiếm yêu cầu/thông báo | E8: Chi tiết thông báo hướng dẫn | H8: Danh sách đơn yêu cầu
C9: ③ Không có | D9: ④ Không có | E9: ⑤ Trạng thái yêu cầu thông báo = 「Đang chờ yêu cầu thông báo」, 「Lưu tạm thời」 | F9: ⑥ Trạng thái yêu cầu/thông báo ＝「Đang yêu cầu/thông báo」 | G9: ⑦ Trạng thái yêu cầu thông báo ＝ "Đã tiếp nhận", "Đang xử lý", "Hoàn thành" | H9: ⑧ Trạng thái yêu cầu/thông báo ＝「Đang chờ yêu cầu/thông báo」, 「Lưu tạm thời」 ※ Giống với ⑤ | I9: ⑨ Trạng thái yêu cầu/thông báo ＝「Đang yêu cầu/thông báo」 ※ Giống với ⑥ | J9: ⑩ Trạng thái yêu cầu thông báo ＝ "Đã tiếp nhận", "Đang xử lý", "Hoàn thành" ※ Giống như ⑦
A10: 1 | B10: Quay lại | C10: Chỉ hiển thị | D10: Chỉ hiển thị | E10: Chỉ hiển thị | F10: Chỉ hiển thị | G10: Chỉ hiển thị | H10: Chỉ hiển thị | I10: Chỉ hiển thị | J10: Chỉ hiển thị
A11: 2 | B11: Khu vực hiển thị chung cho đơn yêu cầu/khai báo | C11: Chỉ hiển thị | D11: Chỉ hiển thị | E11: Chỉ hiển thị | F11: Chỉ hiển thị | G11: Chỉ hiển thị | H11: Chỉ hiển thị | I11: Chỉ hiển thị | J11: Chỉ hiển thị | K11: Điều kiện hiển thị là 【Tài liệu thiết kế cơ bản】Xác nhận dữ liệu nhân viên_Thiết kế màn hình Tham chiếu
A12: 5 | B12: Khu vực thông tin nhân viên | C12: Chỉ hiển thị | D12: Chỉ hiển thị | E12: Ẩn | F12: Ẩn | G12: Ẩn | H12: Ẩn | I12: Ẩn | J12: Ẩn
A13: 6 | B13: Tên công ty | C13: Chỉ hiển thị | D13: Chỉ hiển thị | E13: Ẩn | F13: Ẩn | G13: Ẩn | H13: Ẩn | I13: Ẩn | J13: Ẩn
A14: 7 | B14: Mã số nhân viên | C14: Chỉ hiển thị | D14: Chỉ hiển thị | E14: Ẩn | F14: Ẩn | G14: Ẩn | H14: Ẩn | I14: Ẩn | J14: Ẩn
A15: 8 | B15: Tên nhân viên | C15: Chỉ hiển thị | D15: Chỉ hiển thị | E15: Ẩn | F15: Ẩn | G15: Ẩn | H15: Ẩn | I15: Ẩn | J15: Ẩn
A16: 9 | B16: Mã cơ sở bảo hiểm xã hội | C16: Chỉ hiển thị | D16: Chỉ hiển thị | E16: Ẩn | F16: Ẩn | G16: Ẩn | H16: Ẩn | I16: Ẩn | J16: Ẩn
A17: 10 | B17: Khu vực có/không có số My Number | C17: Chỉ hiển thị | D17: Chỉ hiển thị | E17: Ẩn | F17: Ẩn | G17: Ẩn | H17: Ẩn | I17: Ẩn | J17: Ẩn
A18: 11 | B18: Số My Number | C18: Chỉ hiển thị | D18: Chỉ hiển thị | E18: Ẩn | F18: Ẩn | G18: Ẩn | H18: Ẩn | I18: Ẩn | J18: Ẩn
A19: 12 | B19: Khu vực ý chí đăng ký | C19: Chỉ hiển thị | D19: Chỉ hiển thị | E19: Chỉ hiển thị | F19: Chỉ hiển thị | G19: Chỉ hiển thị | H19: Chỉ hiển thị | I19: Chỉ hiển thị | J19: Chỉ hiển thị | K19: Tham chiếu kiểm soát hiển thị theo mục lựa chọn
A20: 13 | B20: Ý định đăng ký trợ cấp | C20: Chỉ hiển thị | D20: Chỉ hiển thị | E20: Có thể hiển thị/nhập | F20: Chỉ hiển thị | G20: Chỉ hiển thị | H20: Có thể hiển thị/nhập | I20: Chỉ hiển thị | J20: Chỉ hiển thị | K20: Tham chiếu kiểm soát hiển thị theo mục lựa chọn
A21: 14 | B21: Đồng ý đăng ký tiền lương | C21: Chỉ hiển thị | D21: Chỉ hiển thị | E21: Có thể hiển thị/nhập | F21: Chỉ hiển thị | G21: Chỉ hiển thị | H21: Có thể hiển thị/nhập | I21: Chỉ hiển thị | J21: Chỉ hiển thị | K21: Tham chiếu kiểm soát hiển thị theo mục lựa chọn
A22: 15 | B22: Khu vực thông tin tài khoản nhận trợ cấp | C22: Chỉ hiển thị | D22: Chỉ hiển thị | E22: Chỉ hiển thị | F22: Chỉ hiển thị | G22: Chỉ hiển thị | H22: Chỉ hiển thị | I22: Chỉ hiển thị | J22: Chỉ hiển thị | K22: Tham chiếu kiểm soát hiển thị theo mục lựa chọn
A23: 16 | B23: Phân loại tổ chức tài chính | C23: Chỉ hiển thị | D23: Chỉ hiển thị | E23: Có thể hiển thị/nhập | F23: Chỉ hiển thị | G23: Chỉ hiển thị | H23: Có thể hiển thị/nhập | I23: Chỉ hiển thị | J23: Chỉ hiển thị | K23: Tham chiếu kiểm soát hiển thị theo mục lựa chọn
A24: 17 | B24: Ký hiệu | C24: Chỉ hiển thị | D24: Chỉ hiển thị | E24: Có thể hiển thị/nhập | F24: Chỉ hiển thị | G24: Chỉ hiển thị | H24: Có thể hiển thị/nhập | I24: Chỉ hiển thị | J24: Chỉ hiển thị | K24: Tham chiếu kiểm soát hiển thị theo mục lựa chọn
A25: 18 | B25: Số | C25: Chỉ hiển thị | D25: Chỉ hiển thị | E25: Có thể hiển thị/nhập | F25: Chỉ hiển thị | G25: Chỉ hiển thị | H25: Có thể hiển thị/nhập | I25: Chỉ hiển thị | J25: Chỉ hiển thị | K25: Tham chiếu kiểm soát hiển thị theo mục lựa chọn
A26: 19 | B26: Mã tổ chức tài chính | C26: Chỉ hiển thị | D26: Chỉ hiển thị | E26: Có thể hiển thị/nhập | F26: Chỉ hiển thị | G26: Chỉ hiển thị | H26: Có thể hiển thị/nhập | I26: Chỉ hiển thị | J26: Chỉ hiển thị | K26: Tham chiếu kiểm soát hiển thị theo mục lựa chọn
A27: 20 | B27: Tên tổ chức tài chính | C27: Chỉ hiển thị | D27: Chỉ hiển thị | E27: Có thể hiển thị/nhập | F27: Chỉ hiển thị | G27: Chỉ hiển thị | H27: Có thể hiển thị/nhập | I27: Chỉ hiển thị | J27: Chỉ hiển thị | K27: Tham chiếu kiểm soát hiển thị theo mục lựa chọn
A28: 21 | B28: Mã chi nhánh | C28: Chỉ hiển thị | D28: Chỉ hiển thị | E28: Có thể hiển thị/nhập | F28: Chỉ hiển thị | G28: Chỉ hiển thị | H28: Có thể hiển thị/nhập | I28: Chỉ hiển thị | J28: Chỉ hiển thị | K28: Tham chiếu kiểm soát hiển thị theo mục lựa chọn
A29: 22 | B29: Tên chi nhánh | C29: Chỉ hiển thị | D29: Chỉ hiển thị | E29: Có thể hiển thị/nhập | F29: Chỉ hiển thị | G29: Chỉ hiển thị | H29: Có thể hiển thị/nhập | I29: Chỉ hiển thị | J29: Chỉ hiển thị | K29: Tham chiếu kiểm soát hiển thị theo mục lựa chọn
A30: 23 | B30: Số tài khoản | C30: Chỉ hiển thị | D30: Chỉ hiển thị | E30: Có thể hiển thị/nhập | F30: Chỉ hiển thị | G30: Chỉ hiển thị | H30: Có thể hiển thị/nhập | I30: Chỉ hiển thị | J30: Chỉ hiển thị | K30: Tham chiếu kiểm soát hiển thị theo mục lựa chọn
... A32: 25 | B32: Tài liệu đính kèm | C32: Chỉ hiển thị | D32: Chỉ hiển thị | E32: Có thể hiển thị/nhập | F32: Chỉ hiển thị | G32: Chỉ hiển thị | H32: Có thể hiển thị/nhập | I32: Chỉ hiển thị | J32: Chỉ hiển thị | K32: Tham chiếu kiểm soát hiển thị theo mục lựa chọn
A33: 26 | B33: Khu vực dành cho người phụ trách nội bộ sử dụng | C33: Ẩn | D33: Chỉ hiển thị | E33: Ẩn | F33: Ẩn | G33: Ẩn | H33: Ẩn | I33: Ẩn | J33: Ẩn
A34: 27 | B34: Cột dành cho người phụ trách nội bộ | C34: Ẩn | D34: Có thể hiển thị/nhập | E34: Ẩn | F34: Ẩn | G34: Ẩn | H34: Ẩn | I34: Ẩn | J34: Ẩn
A35: 28 | B35: Vô hiệu hóa | C35: Ẩn | D35: Có thể hiển thị/nhập | E35: Ẩn | F35: Ẩn | G35: Ẩn | H35: Ẩn | I35: Ẩn | J35: Ẩn
A36: 29 | B36: Lưu tạm thời | C36: Ẩn | D36: Vô hiệu hóa | E36: Kích hoạt | F36: Vô hiệu hóa | G36: Vô hiệu hóa | H36: Kích hoạt | I36: Vô hiệu hóa | J36: Vô hiệu hóa | K36: Điều khiển theo trạng thái
A37: 30 | B37: Yêu cầu / Thông báo | C37: Ẩn | D37: Vô hiệu hóa | E37: Kích hoạt | F37: Vô hiệu hóa | G37: Vô hiệu hóa | H37: Kích hoạt | I37: Vô hiệu hóa | J37: Vô hiệu hóa | K37: Điều khiển theo trạng thái
A38: 31 | B38: Thu hồi | C38: Ẩn | D38: Vô hiệu hóa | E38: Vô hiệu hóa | F38: Kích hoạt | G38: Vô hiệu hóa | H38: Vô hiệu hóa | I38: Kích hoạt | J38: Vô hiệu hóa | K38: Điều khiển theo trạng thái
A39: 32 | B39: Đăng ký | C39: Ẩn | D39: Kích hoạt | E39: Ẩn | F39: Ẩn | G39: Ẩn | H39: Ẩn | I39: Ẩn | J39: Ẩn | K39: Điều khiển theo trạng thái
A40: 33 | B40: Lịch sử xử lý | C40: Ẩn | D40: Kích hoạt | E40: Ẩn | F40: Ẩn | G40: Ẩn | H40: Ẩn | I40: Ẩn | J40: Ẩn
A51: 【Bổ sung】

Sheet ★ Kiểm soát theo trạng thái
A6: ■ Kiểm soát cập nhật theo quyền/trạng thái
C7: HROne | G7: Nhân viên khách hàng
C8: Có quyền khách hàng | F8: Không có quyền khách hàng
C9: Có quyền nghiệp vụ | E9: Không có quyền nghiệp vụ
C10: Người tạo thông báo hướng dẫn | D10: Khác
A11: 1 | B11: Đang chờ hướng dẫn | C11: Tham chiếu Cờ vô hiệu hóa Nhập cột dành cho người phụ trách | D11: Tham chiếu Cờ vô hiệu hóa Nhập cột dành cho người phụ trách | E11: ー | F11: ー | G11: ー
A12: 2 | B12: Đang chờ yêu cầu/khai báo | E12: Chỉ tham chiếu | F12: ー | G12: Có thể tham chiếu/cập nhật
A13: 3 | B13: Lưu tạm thời | C13: ー | D13: ー | E13: ー | F13: ー | G13: ー
A14: 4 | B14: Đang yêu cầu/thông báo | C14: Tham chiếu Cờ vô hiệu hóa Nhập cột dành cho người phụ trách | D14: Tham chiếu Cờ vô hiệu hóa Nhập cột dành cho người phụ trách | E14: Chỉ tham chiếu | F14: ー | G14: Có thể tham chiếu/thu hồi
A15: 5 | B15: Đang chọn không cần thông báo | C15: ー | D15: ー | E15: ー | F15: ー | G15: ー
A16: 6 | B16: Đã tiếp nhận | C16: Tham chiếu Cờ vô hiệu hóa Nhập cột dành cho người phụ trách | D16: Tham chiếu Cờ vô hiệu hóa Nhập cột dành cho người phụ trách | E16: Chỉ tham chiếu | F16: ー | G16: Chỉ tham chiếu
A17: 7 | B17: Đã tiếp nhận (Không cần thông báo) | C17: ー | D17: ー | E17: ー | F17: ー | G17: ー
A18: 8 | B18: Đang xử lý | C18: Tham chiếu Cờ vô hiệu hóa Nhập cột dành cho người phụ trách | D18: Tham chiếu Cờ vô hiệu hóa Nhập cột dành cho người phụ trách | E18: Chỉ tham chiếu | F18: ー | G18: Chỉ tham chiếu
A19: 9 | B19: Hoàn thành | F19: ー | H19: ※ Việc hiển thị nút xử lý cũng tuân theo quyền này
A22: ■ Kiểm soát nút xử lý theo trạng thái
A24: Trường hợp là người phụ trách HROne/HRP
C25: Lịch sử xử lý | D25: Đăng ký
A28: 1 | B28: Đang chờ hướng dẫn | C28: 〇 | D28: 〇
A29: 2 | B29: Đang chờ yêu cầu/khai báo | C29: 〇 | D29: 〇
A30: 3 | B30: Lưu tạm thời | C30: ー | D30: ー
A31: 4 | B31: Đang yêu cầu/thông báo | C31: 〇 | D31: 〇
A32: 5 | B32: Đang chọn không cần thông báo | C32: ー | D32: ー
A33: 6 | B33: Đã tiếp nhận | C33: 〇 | D33: 〇
A34: 7 | B34: Đã tiếp nhận (Không cần thông báo) | C34: ー | D34: ー
A35: 8 | B35: Đang xử lý | C35: 〇 | D35: 〇
A36: 9 | B36: Hoàn thành | C36: 〇 | D36: 〇
C38: 〇 Kích hoạt
C39: ー Không hoạt động
A41: Trường hợp là nhân viên khách hàng
C42: Lưu tạm thời | D42: Yêu cầu / Thông báo | E42: Thu hồi
A45: 1 | B45: Đang chờ hướng dẫn | C45: ー | D45: ー | E45: ー
A46: 2 | B46: Đang chờ yêu cầu/khai báo | C46: 〇 | D46: 〇 | E46: ー
A47: 3 | B47: Lưu tạm thời | C47: ー | D47: ー | E47: ー
A48: 4 | B48: Đang yêu cầu/thông báo | C48: ー | D48: ー | E48: 〇
A49: 5 | B49: Đang chọn không cần thông báo | C49: ー | D49: ー | E49: ー
A50: 6 | B50: Đã tiếp nhận | C50: ー | D50: ー | E50: ー
A51: 7 | B51: Đã tiếp nhận (Không cần thông báo) | C51: ー | D51: ー | E51: ー
A52: 8 | B52: Đang xử lý | C52: ー | D52: ー | E52: ー
A53: 9 | B53: Hoàn thành | C53: ー | D53: ー | E53: ー
C55: 〇 Kích hoạt
...

Sheet Kiểm soát hiển thị theo hạng mụ
B6: ■ Kiểm soát hiển thị mục màn hình
B7: Hiển thị 1 | C7: Số My Number | D7: Có | E7: 〇 | F7: 〇 | G7: 〇 | H7: 〇 | I7: 〇
D8: Không có | J8: 〇 | K8: 〇 | L8: 〇 | M8: 〇 | N8: 〇
B9: Hiển thị 2 | C9: Ý định đăng ký | D9: Chưa chọn | E9: 〇 | J9: 〇
D10: Đăng ký | F10: 〇 | G10: 〇 | H10: 〇 | K10: 〇 | L10: 〇 | M10: 〇
D11: Không đăng ký | I11: 〇 | N11: 〇
B12: Hiển thị 2-1 | C12: Đồng ý đăng ký tiền lương | D12: Chưa chọn | E12: Ẩn | F12: Ẩn | G12: Ẩn | H12: Ẩn | I12: 〇 | J12: Ẩn | K12: Ẩn | L12: Ẩn | M12: Ẩn | N12: 〇 | O12: Hiển thị 2: Trường hợp ý định đăng ký là "Đăng ký" thì sẽ ẩn
B13: Hiển thị 3 | C13: Phân loại tổ chức tài chính | D13: Chưa chọn | E13: ー | F13: 〇 | I13: ー | J13: ー | K13: 〇 | N13: Ẩn | O13: Hiển thị 2: Trường hợp ý định đăng ký là "Không đăng ký" thì sẽ ẩn
D14: Ngân hàng Yucho | E14: Ẩn | G14: 〇 | I14: Ẩn | J14: Ẩn | L14: 〇 | N14: Ẩn
D15: Các tổ chức tài chính khác | E15: Ẩn | H15: 〇 | I15: Ẩn | J15: Ẩn | M15: 〇 | N15: Ẩn
B16: Hiển thị 4 | C16: Ký hiệu - Số | E16: Ẩn | F16: Ẩn | G16: Hiển thị | H16: Ẩn | I16: Ẩn | J16: Ẩn | K16: Ẩn | L16: Hiển thị | M16: Ẩn | N16: Ẩn | O16: Hiển thị 2: Trường hợp ý định đăng ký là "Không đăng ký" thì sẽ ẩn
C17: Mã tổ chức tài chính | E17: Ẩn | F17: Ẩn | G17: Ẩn | H17: Hiển thị | I17: Ẩn | J17: Ẩn | K17: Ẩn | L17: Ẩn | M17: Hiển thị | N17: Ẩn | O17: Hiển thị 3: Kiểm soát hiển thị tùy theo phân loại tổ chức tài chính
C18: Tên tổ chức tài chính | E18: Ẩn | F18: Ẩn | G18: Ẩn | H18: Hiển thị | I18: Ẩn | J18: Ẩn | K18: Ẩn | L18: Ẩn | M18: Hiển thị | N18: Ẩn
C19: Mã chi nhánh | E19: Ẩn | F19: Ẩn | G19: Ẩn | H19: Hiển thị | I19: Ẩn | J19: Ẩn | K19: Ẩn | L19: Ẩn | M19: Hiển thị | N19: Ẩn
C20: Tên trụ sở chính/chi nhánh | E20: Ẩn | F20: Ẩn | G20: Ẩn | H20: Hiển thị | I20: Ẩn | J20: Ẩn | K20: Ẩn | L20: Ẩn | M20: Hiển thị | N20: Ẩn
C21: Số tài khoản | E21: Ẩn | F21: Ẩn | G21: Ẩn | H21: Hiển thị | I21: Ẩn | J21: Ẩn | K21: Ẩn | L21: Ẩn | M21: Hiển thị | N21: Ẩn
B22: Hiển thị 5 | C22: Tài liệu đính kèm | E22: Ẩn | F22: Ẩn | G22: Ẩn | H22: Ẩn | I22: Ẩn | J22: Ẩn | K22: Hiển thị | L22: Hiển thị | M22: Hiển thị | N22: Hiển thị | O22: Hiển thị 1: Ẩn nếu My Number là "Có"
B24: Trường hợp ẩn theo điều kiện thì xóa toàn bộ dữ liệu.
B25: <Ví dụ>
B26: Khi chọn Phân loại tổ chức tài chính = Ngân hàng Yucho, sau khi nhập Ký hiệu-Số, nếu thay đổi Phân loại tổ chức tài chính = Tổ chức tài chính khác thì sẽ xóa Ký hiệu-Số.
B28: ■ Kiểm tra nhập liệu
B29: Hạng mục | C29: Xác thực | I29: Điều kiện bắt buộc
C30: Kiểm tra | D30: Thông báo lỗi | I30: Điều kiện kiểm tra | N30: Thông báo lỗi
B31: Ký hiệu | C31: 5 chữ số | D31: Vui lòng nhập ký hiệu bằng 5 chữ số nửa chiều rộng | I31: Phân loại tổ chức tài chính = Trường hợp là Ngân hàng Yucho | N31: Ký hiệu là mục bắt buộc nhập.
B32: Số | C32: 8 chữ số | D32: Vui lòng nhập số bằng 8 chữ số nửa chiều rộng | I32: Phân loại tổ chức tài chính = Trường hợp là Ngân hàng Yucho | N32: Số là mục bắt buộc nhập.
B33: Mã tổ chức tài chính | C33: Số 4 chữ số | D33: Vui lòng nhập mã định chế tài chính bằng 4 chữ số nửa chiều rộng | I33: Phân loại tổ chức tài chính = Trường hợp là Tổ chức tài chính khác | N33: Mã định chế tài chính là mục bắt buộc nhập.
B34: Mã chi nhánh | C34: Số 3 chữ số | D34: Vui lòng nhập mã chi nhánh bằng 3 chữ số nửa chiều rộng | I34: Phân loại tổ chức tài chính = Trường hợp là Tổ chức tài chính khác | N34: Mã chi nhánh là mục bắt buộc nhập.
B35: Số tài khoản | C35: Số 7 chữ số | D35: Vui lòng nhập số tài khoản bằng 7 chữ số nửa chiều rộng | I35: Phân loại tổ chức tài chính = Trường hợp là Tổ chức tài chính khác | N35: Số tài khoản là mục bắt buộc nhập.
B36: Tệp đính kèm | C36: Kiểm tra chung | D36: ※ Lỗi chung | I36: Số My Number = Trường hợp không có | N36: 【Tên tệp đính kèm】 là bắt buộc phải đính kèm.

Sheet Tham khảo
B2: Bảo hiểm thất nghiệp: Thủ tục bắt đầu nhận trợ cấp cho người cao tuổi
AL3: ★ Giải thích
B5: Vui lòng nộp đơn trước yyyy/mm/dd (aaa) trước ngày này | AE5: Đang chờ yêu cầu/khai báo | AL5: Hạn chót nộp:
AM6: Hiển thị hạn chót đã nhập từ hướng dẫn của HRP
C8: Tên công ty | AL8: Thông tin nhân viên:
AM9: Hiển thị khi người phụ trách HRO/HRP xem màn hình này
C10: Mã số nhân viên | AM10: Ẩn đối với màn hình của nhân viên
C12: Tên nhân viên
C16: Ý định đăng ký trợ cấp | H16: (Bắt buộc) | K16: 〇 Đồng ý với nội dung dưới đây và đăng ký nhận trợ cấp | T16: 〇 Không đăng ký | AL16: 《Người không đăng ký trợ cấp cho người cao tuổi》:
AM17: Chỉ có thể chỉnh sửa/bắt buộc khi 「Ý định xin cấp phép = Không xin cấp phép」
D18: ・ | E18: Thực hiện các thủ tục cần thiết để xin cấp tiền trợ cấp
D19: ・ | E19: Trong trường hợp chuyển công tác, việc xin cấp tiền trợ cấp sẽ tiếp tục được thực hiện tại công ty nơi chuyển đến
C22: 《Đối với những người không xin cấp tiền trợ cấp cao tuổi》
D23: Ngay cả trường hợp không xin cấp tiền trợ cấp, bạn vẫn cần phải đăng ký tiền lương.
D24: □ | E24: Tôi đồng ý với việc đăng ký tiền lương
B28: Thông tin tài khoản nhận tiền trợ cấp | AL28: Thông tin tài khoản nhận tiền trợ cấp:
AM29: Hiển thị khi thỏa mãn các điều kiện dưới đây.
C30: Phân loại tổ chức tài chính | G30: (Bắt buộc) | I30: 〇 | J30: Ngân hàng Yucho | O30: 〇 | P30: Các tổ chức tài chính khác | AM30: (Điều kiện)
AM31: "Ý định đăng ký trợ cấp = Đăng ký"
C32: 《Trường hợp Ngân hàng Yucho》
D34: Ký hiệu － Số tài khoản (5 chữ số － 8 chữ số) | J34: 12345 | N34: － | O34: 12345678
C37: 《Trường hợp các tổ chức tài chính khác》
AL38: Thông tin tài khoản:
D39: Mã định danh tổ chức tài chính (4 chữ số) | J39: 0000 | AM39: Kiểm soát khả năng chỉnh sửa thông tin khác tùy theo phân loại tổ chức tài chính
AM40: Phân loại tổ chức tài chính | AS40: Mục có thể chỉnh sửa
D41: Tên tổ chức tài chính | AM41: Ngân hàng Yucho | AS41: Chỉ "Ký hiệu - Số hiệu"
AM42: Các tổ chức tài chính khác | AS42: Ngoài "Ký hiệu - Số hiệu"
D43: Mã cửa hàng (3 chữ số) | J43: 000
D45: Tên trụ sở chính/chi nhánh
D47: Số tài khoản (7 chữ số) | J47: 0123456 | R47: ※ Trường hợp có 6 chữ số, vui lòng thêm số "0" vào phía trước.
AL51: Tài liệu đính kèm:
B52: Tài liệu đính kèm | AM52: Hiển thị các mục sau nếu đáp ứng các điều kiện dưới đây.
AM53: (Điều kiện)
C54: (Bắt buộc) Một trong các giấy tờ sau: Bằng lái xe, Hộ chiếu, hoặc Bản sao phiếu cư trú (không ghi số My Number) | AF54: ？ | AM54: Thông tin "Có/Không MN = Không" theo hướng dẫn từ HRP
C55: ※ Trường hợp là phiếu cư trú, phải là bản được cấp trong vòng 3 tháng
C56: Tệp đính kèm | AL56: ？ | AM56: ：
AM57: Nhấp để hiển thị giải thích chi tiết
AL60: Yêu cầu/Thông báo:
AM61: Trường hợp dưới đây sẽ kiểm tra lỗi. Yêu cầu người dùng tích chọn đồng ý.
AM62: "Ý định đăng ký = Không đăng ký" và "Đồng ý đăng ký tiền lương = Không tích chọn"
...

Sheet Cài đặt
A1: Có hiệu lực/Không có hiệu lực | B1: Loại tạo BIS | C1: Người xử lý [Yêu cầu] | D1: Người xử lý [Phê duyệt] | E1: Người xử lý [Phê duyệt động/Xác nhận/Bố trí ngang/Bố trí dọc] | F1: Loại nút
A2: Hữu hiệu | B2: BAM | C2: Không chỉ định | D2: Không chỉ định | E2: Không chỉ định | F2: Bắt đầu
A3: Vô hiệu hóa | B3: WF | C3: Người dùng | D3: Người dùng | E3: Người dùng | F3: Kết thúc
C4: Tổ chức | D4: Tổ chức | E4: Tổ chức | F4: Yêu cầu
C5: Vai trò | D5: Vai trò | E5: Vai trò | F5: Yêu cầu
C6: Nhóm công khai | D6: Nhóm công khai | E6: Nhóm công khai | F6: Phê duyệt
C7: Chức vụ | D7: Chức vụ | E7: Chức vụ | F7: Phê duyệt động
C8: Vai trò | D8: Vai trò | E8: Vai trò | F8: Hệ thống
C9: Tổ chức + Chức vụ | D9: Tổ chức + Chức vụ | E9: Tổ chức + Chức vụ | F9: Xác nhận
C10: Nhóm công khai + Vai trò | D10: Nhóm công khai + Vai trò | E10: Nhóm công khai + Vai trò | F10: Bắt đầu đồng bộ
C11: Tổ chức + Role | D11: Tổ chức + Role | E11: Tổ chức + Role | F11: Kết thúc đồng bộ
C12: Nhóm công khai + Role | D12: Nhóm công khai + Role | E12: Nhóm công khai + Role | F12: Bắt đầu phân nhánh
C13: Tổ chức và tất cả tổ chức cấp trên | D13: Người bắt đầu yêu cầu/xử lý | E13: Tổ chức và tất cả tổ chức cấp trên | F13: Kết thúc phân nhánh
C14: Tổ chức và tất cả tổ chức cấp trên + Chức vụ | D14: Tổ chức trực thuộc của người bắt đầu yêu cầu/xử lý | E14: Tổ chức và tất cả tổ chức cấp trên + Chức vụ | F14: Bố trí ngang
C15: Tất cả tổ chức và tổ chức cấp trên + vai trò | D15: Tổ chức trực thuộc của người bắt đầu yêu cầu/xử lý + chức vụ | E15: Tất cả tổ chức và tổ chức cấp trên + vai trò | F15: Bố trí dọc
... C18: Tổ chức và tất cả các tổ chức cấp dưới + Vai trò | D18: Tổ chức cấp trên + Chức vụ của người bắt đầu yêu cầu/xử lý | E18: Tổ chức và tất cả các tổ chức cấp dưới + Vai trò | F18: Kết thúc mẫu
D19: Tổ chức cấp trên + Vai trò của người bắt đầu yêu cầu/xử lý | F19: Nhận xét
D20: Tất cả tổ chức cấp trên của người yêu cầu/người bắt đầu xử lý | F20: Swimlane
D21: Tất cả tổ chức cấp trên của người yêu cầu/người bắt đầu xử lý + Chức vụ
D22: Tất cả tổ chức cấp trên của người yêu cầu/người bắt đầu xử lý + Vai trò
D23: Tổ chức cấp dưới của người bắt đầu yêu cầu/xử lý
D24: Tổ chức cấp dưới của người bắt đầu yêu cầu/xử lý + Chức vụ
D25: Tổ chức cấp dưới của người bắt đầu yêu cầu/xử lý + Vai trò
D26: Tất cả tổ chức cấp dưới của người bắt đầu yêu cầu/xử lý
D27: Tất cả tổ chức cấp dưới của người bắt đầu yêu cầu/xử lý + Chức vụ
D28: Tất cả tổ chức cấp dưới của người yêu cầu/người bắt đầu xử lý + Role
D29: Tổ chức và tất cả tổ chức cấp trên
D30: Tổ chức và tất cả tổ chức cấp trên + Chức vụ
D31: Tất cả tổ chức và tổ chức cấp trên + vai trò
D32: Tổ chức và tất cả các tổ chức cấp dưới
... D34: Tổ chức và tất cả các tổ chức cấp dưới + Vai trò
