Workbook
Name __tst2: {#N/A,#N/A,TRUE,"カスタマイズ仕様書";#N/A,#N/A,TRUE,"Ｉ・Ｏ関連表(1)";#N/A,#N/A,TRUE,"Ｉ・Ｏ関連表(2)";#N/A,#N/A,TRUE,"Ｉ・Ｏ関連表(3)";#N/A,#N/A,TRUE,"レポート記述書";#N/A,#N/A,TRUE,"画面記述書"}
Name __tst2: {#N/A,#N/A,TRUE,"カスタマイズ仕様書";#N/A,#N/A,TRUE,"Ｉ・Ｏ関連表(1)";#N/A,#N/A,TRUE,"Ｉ・Ｏ関連表(2)";#N/A,#N/A,TRUE,"Ｉ・Ｏ関連表(3)";#N/A,#N/A,TRUE,"レポート記述書";#N/A,#N/A,TRUE,"画面記述書"}
Name __tst2: {#N/A,#N/A,TRUE,"カスタマイズ仕様書";#N/A,#N/A,TRUE,"Ｉ・Ｏ関連表(1)";#N/A,#N/A,TRUE,"Ｉ・Ｏ関連表(2)";#N/A,#N/A,TRUE,"Ｉ・Ｏ関連表(3)";#N/A,#N/A,TRUE,"レポート記述書";#N/A,#N/A,TRUE,"画面記述書"}
Name __tst2: {#N/A,#N/A,TRUE,"カスタマイズ仕様書";#N/A,#N/A,TRUE,"Ｉ・Ｏ関連表(1)";#N/A,#N/A,TRUE,"Ｉ・Ｏ関連表(2)";#N/A,#N/A,TRUE,"Ｉ・Ｏ関連表(3)";#N/A,#N/A,TRUE,"レポート記述書";#N/A,#N/A,TRUE,"画面記述書"}
Name __tst2: {#N/A,#N/A,TRUE,"カスタマイズ仕様書";#N/A,#N/A,TRUE,"Ｉ・Ｏ関連表(1)";#N/A,#N/A,TRUE,"Ｉ・Ｏ関連表(2)";#N/A,#N/A,TRUE,"Ｉ・Ｏ関連表(3)";#N/A,#N/A,TRUE,"レポート記述書";#N/A,#N/A,TRUE,"画面記述書"}
Name __tst2: {#N/A,#N/A,TRUE,"カスタマイズ仕様書";#N/A,#N/A,TRUE,"Ｉ・Ｏ関連表(1)";#N/A,#N/A,TRUE,"Ｉ・Ｏ関連表(2)";#N/A,#N/A,TRUE,"Ｉ・Ｏ関連表(3)";#N/A,#N/A,TRUE,"レポート記述書";#N/A,#N/A,TRUE,"画面記述書"}
Name A4縦_フッタロゴなし: {#N/A,#N/A,TRUE,"カスタマイズ仕様書";#N/A,#N/A,TRUE,"Ｉ・Ｏ関連表(1)";#N/A,#N/A,TRUE,"Ｉ・Ｏ関連表(2)";#N/A,#N/A,TRUE,"Ｉ・Ｏ関連表(3)";#N/A,#N/A,TRUE,"レポート記述書";#N/A,#N/A,TRUE,"画面記述書"}
Name A4縦_フッタロゴなし: {#N/A,#N/A,TRUE,"カスタマイズ仕様書";#N/A,#N/A,TRUE,"Ｉ・Ｏ関連表(1)";#N/A,#N/A,TRUE,"Ｉ・Ｏ関連表(2)";#N/A,#N/A,TRUE,"Ｉ・Ｏ関連表(3)";#N/A,#N/A,TRUE,"レポート記述書";#N/A,#N/A,TRUE,"画面記述書"}
Name A4縦_フッタロゴなし: {#N/A,#N/A,TRUE,"カスタマイズ仕様書";#N/A,#N/A,TRUE,"Ｉ・Ｏ関連表(1)";#N/A,#N/A,TRUE,"Ｉ・Ｏ関連表(2)";#N/A,#N/A,TRUE,"Ｉ・Ｏ関連表(3)";#N/A,#N/A,TRUE,"レポート記述書";#N/A,#N/A,TRUE,"画面記述書"}
Name A4縦_フッタロゴなし: {#N/A,#N/A,TRUE,"カスタマイズ仕様書";#N/A,#N/A,TRUE,"Ｉ・Ｏ関連表(1)";#N/A,#N/A,TRUE,"Ｉ・Ｏ関連表(2)";#N/A,#N/A,TRUE,"Ｉ・Ｏ関連表(3)";#N/A,#N/A,TRUE,"レポート記述書";#N/A,#N/A,TRUE,"画面記述書"}
Name A4縦_フッタロゴなし: {#N/A,#N/A,TRUE,"カスタマイズ仕様書";#N/A,#N/A,TRUE,"Ｉ・Ｏ関連表(1)";#N/A,#N/A,TRUE,"Ｉ・Ｏ関連表(2)";#N/A,#N/A,TRUE,"Ｉ・Ｏ関連表(3)";#N/A,#N/A,TRUE,"レポート記述書";#N/A,#N/A,TRUE,"画面記述書"}
Name A4縦_フッタロゴなし: {#N/A,#N/A,TRUE,"カスタマイズ仕様書";#N/A,#N/A,TRUE,"Ｉ・Ｏ関連表(1)";#N/A,#N/A,TRUE,"Ｉ・Ｏ関連表(2)";#N/A,#N/A,TRUE,"Ｉ・Ｏ関連表(3)";#N/A,#N/A,TRUE,"レポート記述書";#N/A,#N/A,TRUE,"画面記述書"}
Name A4縦_雛形フッタロゴなし: {#N/A,#N/A,TRUE,"カスタマイズ仕様書";#N/A,#N/A,TRUE,"Ｉ・Ｏ関連表(1)";#N/A,#N/A,TRUE,"Ｉ・Ｏ関連表(2)";#N/A,#N/A,TRUE,"Ｉ・Ｏ関連表(3)";#N/A,#N/A,TRUE,"レポート記述書";#N/A,#N/A,TRUE,"画面記述書"}
Name A4縦_雛形フッタロゴなし: {#N/A,#N/A,TRUE,"カスタマイズ仕様書";#N/A,#N/A,TRUE,"Ｉ・Ｏ関連表(1)";#N/A,#N/A,TRUE,"Ｉ・Ｏ関連表(2)";#N/A,#N/A,TRUE,"Ｉ・Ｏ関連表(3)";#N/A,#N/A,TRUE,"レポート記述書";#N/A,#N/A,TRUE,"画面記述書"}
Name A4縦_雛形フッタロゴなし: {#N/A,#N/A,TRUE,"カスタマイズ仕様書";#N/A,#N/A,TRUE,"Ｉ・Ｏ関連表(1)";#N/A,#N/A,TRUE,"Ｉ・Ｏ関連表(2)";#N/A,#N/A,TRUE,"Ｉ・Ｏ関連表(3)";#N/A,#N/A,TRUE,"レポート記述書";#N/A,#N/A,TRUE,"画面記述書"}
Name A4縦_雛形フッタロゴなし: {#N/A,#N/A,TRUE,"カスタマイズ仕様書";#N/A,#N/A,TRUE,"Ｉ・Ｏ関連表(1)";#N/A,#N/A,TRUE,"Ｉ・Ｏ関連表(2)";#N/A,#N/A,TRUE,"Ｉ・Ｏ関連表(3)";#N/A,#N/A,TRUE,"レポート記述書";#N/A,#N/A,TRUE,"画面記述書"}
Name A4縦_雛形フッタロゴなし: {#N/A,#N/A,TRUE,"カスタマイズ仕様書";#N/A,#N/A,TRUE,"Ｉ・Ｏ関連表(1)";#N/A,#N/A,TRUE,"Ｉ・Ｏ関連表(2)";#N/A,#N/A,TRUE,"Ｉ・Ｏ関連表(3)";#N/A,#N/A,TRUE,"レポート記述書";#N/A,#N/A,TRUE,"画面記述書"}
Name A4縦_雛形フッタロゴなし: {#N/A,#N/A,TRUE,"カスタマイズ仕様書";#N/A,#N/A,TRUE,"Ｉ・Ｏ関連表(1)";#N/A,#N/A,TRUE,"Ｉ・Ｏ関連表(2)";#N/A,#N/A,TRUE,"Ｉ・Ｏ関連表(3)";#N/A,#N/A,TRUE,"レポート記述書";#N/A,#N/A,TRUE,"画面記述書"}
Name aaaaa: {#N/A,#N/A,TRUE,"カスタマイズ仕様書";#N/A,#N/A,TRUE,"Ｉ・Ｏ関連表(1)";#N/A,#N/A,TRUE,"Ｉ・Ｏ関連表(2)";#N/A,#N/A,TRUE,"Ｉ・Ｏ関連表(3)";#N/A,#N/A,TRUE,"レポート記述書";#N/A,#N/A,TRUE,"画面記述書"}
Name aaaaa: {#N/A,#N/A,TRUE,"カスタマイズ仕様書";#N/A,#N/A,TRUE,"Ｉ・Ｏ関連表(1)";#N/A,#N/A,TRUE,"Ｉ・Ｏ関連表(2)";#N/A,#N/A,TRUE,"Ｉ・Ｏ関連表(3)";#N/A,#N/A,TRUE,"レポート記述書";#N/A,#N/A,TRUE,"画面記述書"}
Name aaaaa: {#N/A,#N/A,TRUE,"カスタマイズ仕様書";#N/A,#N/A,TRUE,"Ｉ・Ｏ関連表(1)";#N/A,#N/A,TRUE,"Ｉ・Ｏ関連表(2)";#N/A,#N/A,TRUE,"Ｉ・Ｏ関連表(3)";#N/A,#N/A,TRUE,"レポート記述書";#N/A,#N/A,TRUE,"画面記述書"}
Name aaaaa: {#N/A,#N/A,TRUE,"カスタマイズ仕様書";#N/A,#N/A,TRUE,"Ｉ・Ｏ関連表(1)";#N/A,#N/A,TRUE,"Ｉ・Ｏ関連表(2)";#N/A,#N/A,TRUE,"Ｉ・Ｏ関連表(3)";#N/A,#N/A,TRUE,"レポート記述書";#N/A,#N/A,TRUE,"画面記述書"}
Name aaaaa: {#N/A,#N/A,TRUE,"カスタマイズ仕様書";#N/A,#N/A,TRUE,"Ｉ・Ｏ関連表(1)";#N/A,#N/A,TRUE,"Ｉ・Ｏ関連表(2)";#N/A,#N/A,TRUE,"Ｉ・Ｏ関連表(3)";#N/A,#N/A,TRUE,"レポート記述書";#N/A,#N/A,TRUE,"画面記述書"}
Name aaaaa: {#N/A,#N/A,TRUE,"カスタマイズ仕様書";#N/A,#N/A,TRUE,"Ｉ・Ｏ関連表(1)";#N/A,#N/A,TRUE,"Ｉ・Ｏ関連表(2)";#N/A,#N/A,TRUE,"Ｉ・Ｏ関連表(3)";#N/A,#N/A,TRUE,"レポート記述書";#N/A,#N/A,TRUE,"画面記述書"}
Name BIS作成種類: OFFSET([1]設定!$B$2,,,COUNTA([1]設定!$B:$B)-1)
Name BIS作成種類: OFFSET([2]設定!$B$2,,,COUNTA([2]設定!$B:$B)-1)
Name BIS作成種類: OFFSET([1]設定!$B$2,,,COUNTA([1]設定!$B:$B)-1)
Name BIS作成種類: OFFSET([2]設定!$B$2,,,COUNTA([2]設定!$B:$B)-1)
Name BIS作成種類: OFFSET([2]設定!$B$2,,,COUNTA([2]設定!$B:$B)-1)
Name BIS作成種類: OFFSET(設定!$B$2,,,COUNTA(設定!$B:$B)-1)
Name ｇｇｇｇ: {#N/A,#N/A,TRUE,"カスタマイズ仕様書";#N/A,#N/A,TRUE,"Ｉ・Ｏ関連表(1)";#N/A,#N/A,TRUE,"Ｉ・Ｏ関連表(2)";#N/A,#N/A,TRUE,"Ｉ・Ｏ関連表(3)";#N/A,#N/A,TRUE,"レポート記述書";#N/A,#N/A,TRUE,"画面記述書"}
Name HTML1_1: "[帳票管理資料.xls]集計表!$A$1:$R$32"
Name HTML1_10: ""
Name HTML1_11: 1
Name HTML1_12: "C:\My Documents\MyHTML.htm"
Name HTML1_2: 1
Name HTML1_3: "帳票管理資料.xls"
Name HTML1_4: "集計表"
Name HTML1_5: ""
Name HTML1_6: -4146
Name HTML1_7: -4146
Name HTML1_8: "97/07/14"
Name HTML1_9: "お客様各位"
Name HTMLCount: 1
Name s: {#N/A,#N/A,TRUE,"カスタマイズ仕様書";#N/A,#N/A,TRUE,"Ｉ・Ｏ関連表(1)";#N/A,#N/A,TRUE,"Ｉ・Ｏ関連表(2)";#N/A,#N/A,TRUE,"Ｉ・Ｏ関連表(3)";#N/A,#N/A,TRUE,"レポート記述書";#N/A,#N/A,TRUE,"画面記述書"}
Name s: {#N/A,#N/A,TRUE,"カスタマイズ仕様書";#N/A,#N/A,TRUE,"Ｉ・Ｏ関連表(1)";#N/A,#N/A,TRUE,"Ｉ・Ｏ関連表(2)";#N/A,#N/A,TRUE,"Ｉ・Ｏ関連表(3)";#N/A,#N/A,TRUE,"レポート記述書";#N/A,#N/A,TRUE,"画面記述書"}
Name s: {#N/A,#N/A,TRUE,"カスタマイズ仕様書";#N/A,#N/A,TRUE,"Ｉ・Ｏ関連表(1)";#N/A,#N/A,TRUE,"Ｉ・Ｏ関連表(2)";#N/A,#N/A,TRUE,"Ｉ・Ｏ関連表(3)";#N/A,#N/A,TRUE,"レポート記述書";#N/A,#N/A,TRUE,"画面記述書"}
Name s: {#N/A,#N/A,TRUE,"カスタマイズ仕様書";#N/A,#N/A,TRUE,"Ｉ・Ｏ関連表(1)";#N/A,#N/A,TRUE,"Ｉ・Ｏ関連表(2)";#N/A,#N/A,TRUE,"Ｉ・Ｏ関連表(3)";#N/A,#N/A,TRUE,"レポート記述書";#N/A,#N/A,TRUE,"画面記述書"}
Name s: {#N/A,#N/A,TRUE,"カスタマイズ仕様書";#N/A,#N/A,TRUE,"Ｉ・Ｏ関連表(1)";#N/A,#N/A,TRUE,"Ｉ・Ｏ関連表(2)";#N/A,#N/A,TRUE,"Ｉ・Ｏ関連表(3)";#N/A,#N/A,TRUE,"レポート記述書";#N/A,#N/A,TRUE,"画面記述書"}
Name s: {#N/A,#N/A,TRUE,"カスタマイズ仕様書";#N/A,#N/A,TRUE,"Ｉ・Ｏ関連表(1)";#N/A,#N/A,TRUE,"Ｉ・Ｏ関連表(2)";#N/A,#N/A,TRUE,"Ｉ・Ｏ関連表(3)";#N/A,#N/A,TRUE,"レポート記述書";#N/A,#N/A,TRUE,"画面記述書"}
Name ss: {#N/A,#N/A,TRUE,"カスタマイズ仕様書";#N/A,#N/A,TRUE,"Ｉ・Ｏ関連表(1)";#N/A,#N/A,TRUE,"Ｉ・Ｏ関連表(2)";#N/A,#N/A,TRUE,"Ｉ・Ｏ関連表(3)";#N/A,#N/A,TRUE,"レポート記述書";#N/A,#N/A,TRUE,"画面記述書"}
Name ss: {#N/A,#N/A,TRUE,"カスタマイズ仕様書";#N/A,#N/A,TRUE,"Ｉ・Ｏ関連表(1)";#N/A,#N/A,TRUE,"Ｉ・Ｏ関連表(2)";#N/A,#N/A,TRUE,"Ｉ・Ｏ関連表(3)";#N/A,#N/A,TRUE,"レポート記述書";#N/A,#N/A,TRUE,"画面記述書"}
Name ss: {#N/A,#N/A,TRUE,"カスタマイズ仕様書";#N/A,#N/A,TRUE,"Ｉ・Ｏ関連表(1)";#N/A,#N/A,TRUE,"Ｉ・Ｏ関連表(2)";#N/A,#N/A,TRUE,"Ｉ・Ｏ関連表(3)";#N/A,#N/A,TRUE,"レポート記述書";#N/A,#N/A,TRUE,"画面記述書"}
Name ss: {#N/A,#N/A,TRUE,"カスタマイズ仕様書";#N/A,#N/A,TRUE,"Ｉ・Ｏ関連表(1)";#N/A,#N/A,TRUE,"Ｉ・Ｏ関連表(2)";#N/A,#N/A,TRUE,"Ｉ・Ｏ関連表(3)";#N/A,#N/A,TRUE,"レポート記述書";#N/A,#N/A,TRUE,"画面記述書"}
Name ss: {#N/A,#N/A,TRUE,"カスタマイズ仕様書";#N/A,#N/A,TRUE,"Ｉ・Ｏ関連表(1)";#N/A,#N/A,TRUE,"Ｉ・Ｏ関連表(2)";#N/A,#N/A,TRUE,"Ｉ・Ｏ関連表(3)";#N/A,#N/A,TRUE,"レポート記述書";#N/A,#N/A,TRUE,"画面記述書"}
Name ss: {#N/A,#N/A,TRUE,"カスタマイズ仕様書";#N/A,#N/A,TRUE,"Ｉ・Ｏ関連表(1)";#N/A,#N/A,TRUE,"Ｉ・Ｏ関連表(2)";#N/A,#N/A,TRUE,"Ｉ・Ｏ関連表(3)";#N/A,#N/A,TRUE,"レポート記述書";#N/A,#N/A,TRUE,"画面記述書"}
Name ｔｓｔ: {#N/A,#N/A,TRUE,"カスタマイズ仕様書";#N/A,#N/A,TRUE,"Ｉ・Ｏ関連表(1)";#N/A,#N/A,TRUE,"Ｉ・Ｏ関連表(2)";#N/A,#N/A,TRUE,"Ｉ・Ｏ関連表(3)";#N/A,#N/A,TRUE,"レポート記述書";#N/A,#N/A,TRUE,"画面記述書"}
Name ｔｓｔ: {#N/A,#N/A,TRUE,"カスタマイズ仕様書";#N/A,#N/A,TRUE,"Ｉ・Ｏ関連表(1)";#N/A,#N/A,TRUE,"Ｉ・Ｏ関連表(2)";#N/A,#N/A,TRUE,"Ｉ・Ｏ関連表(3)";#N/A,#N/A,TRUE,"レポート記述書";#N/A,#N/A,TRUE,"画面記述書"}
Name ｔｓｔ: {#N/A,#N/A,TRUE,"カスタマイズ仕様書";#N/A,#N/A,TRUE,"Ｉ・Ｏ関連表(1)";#N/A,#N/A,TRUE,"Ｉ・Ｏ関連表(2)";#N/A,#N/A,TRUE,"Ｉ・Ｏ関連表(3)";#N/A,#N/A,TRUE,"レポート記述書";#N/A,#N/A,TRUE,"画面記述書"}
Name ｔｓｔ: {#N/A,#N/A,TRUE,"カスタマイズ仕様書";#N/A,#N/A,TRUE,"Ｉ・Ｏ関連表(1)";#N/A,#N/A,TRUE,"Ｉ・Ｏ関連表(2)";#N/A,#N/A,TRUE,"Ｉ・Ｏ関連表(3)";#N/A,#N/A,TRUE,"レポート記述書";#N/A,#N/A,TRUE,"画面記述書"}

Sheet Header
A1: ↓元情報入力↓※印刷時は非表示に
A2: プロジェクト名 | I2: システム名（ID) | P2: 分類 | V2: 業務名（ID） | AB2: 名称（ID） | AJ2: Ver． | AL2: 作成者 | AP2: 作成日 | AS2: 更新者 | AW2: 更新日
A3: 従業員ポータル | I3: HROneポータル | P3: 画面設計書 | V3: 依頼届出 | AB3: 雇保給付金開始申請_高年齢 | AJ3: =表紙!AF31 -> 1.1.4 | AL3: ACF | AP3: 45163 | AS3: =OFFSET(更新履歴!N6,COUNTA(更新履歴!N6:N65531)-1,0) -> ACF | AW3: =OFFSET(更新履歴!H6,COUNTA(更新履歴!H6:H65531)-1,0) -> 45957

Sheet 表紙
O3: =Header!A3 -> 従業員ポータル
O4: =Header!I3 -> HROneポータル
O7: 基本設計書
O10: =Header!AB3 -> 雇保給付金開始申請_高年齢
Z21: 作成日 | AF21: =Header!AP3 -> 45163
Z23: 最終更新日 | AF23: =Header!AW3 -> 45957
Z25: 最終更新者 | AF25: =Header!AS3 -> ACF
Z27: レビュー・承認日 | AF27: =OFFSET(更新履歴!AT6,COUNTA(更新履歴!AT6:AT65531)-1,0) -> レビュー・承認日
Z29: レビュー・承認者 | AF29: =OFFSET(更新履歴!AY6,COUNTA(更新履歴!AY6:AY65531)-1,0) -> レビュー・承認者
Z31: バージョン | AF31: =OFFSET(更新履歴!C6,COUNTA(更新履歴!C6:C65531)-1,0) -> 1.1.4

Sheet 更新履歴
A5: No. | C5: Ver. | H5: 作成・変更日 | N5: 作成・変更者 | T5: 作成・変更内容 | AT5: レビュー・承認日 | AY5: レビュー・承認者
A6: 1 | C6: 1.0.0 | H6: 45163 | N6: ACF | T6: 新規作成
A7: 2 | C7: 1.0.1 | H7: 45218 | N7: ACF | T7: モバイル画面イメージ追加
A8: 3 | C8: 1.0.2 | H8: 45243 | N8: ACF | T8: ステータス別制御 ステータス＝依頼届出待ちの制御を修正
A9: 4 | C9: 1.0.3 | H9: 45259 | N9: ACF | T9: 添付ファイルの表示制御終修正
A10: 5 | C10: 1.0.4 | H10: 45264 | N10: ACF | T10: 賃金登録同意の表示制御修正 選択項目別表示制御シート
A11: 6 | C11: 1.0.5 | H11: 45265 | N11: ACF | T11: 添付書類の表示タイミングの制御変更 選択項目別表示シート
A12: 7 | C12: 1.0.6 | H12: 45265 | N12: ACF | T12: 担当者へのの添付ファイル、個別案内通知の表示制御
A13: 8 | C13: 1.1.0 | H13: 45595 | N13: ACF | T13: キット対応
A14: 9 | C14: 1.1.2 | H14: 45713 | N14: ACF | T14: 指摘修正
A15: 10 | C15: 1.1.3 | H15: 45772 | N15: ACF | T15: 指摘修正
A16: 11 | C16: 1.1.4 | H16: 45957 | N16: ACF | T16: 指摘修正

Sheet 画面遷移概要
A5: 【概要】

Sheet ★画面呼び出しパターン
B5: ■画面呼び出しパターン
B6: この画面の呼び出しパターンは以下の通り
B8: 項番 | C8: 呼び出し元画面 | D8: 呼び出しイベント | E8: 画面表示 | F8: ログインユーザ | G8: 呼び出し条件
B9: 1 | C9: 案内通知プレビュー | D9: 依頼届出へのリンク | E9: モーダル | F9: HROne/HRP担当者 | G9: なし
B10: 2 | C10: HROne/HRP担当者向け_依頼・届出検索 | D10: タイトルリンククリック | E10: ポップアップ | F10: HROne/HRP担当者 | G10: なし
B11: 3 | C11: 案内通知詳細 | D11: 依頼届出リンク | E11: 画面遷移 | F11: 顧客従業員 | G11: 依頼届出のステータスが「依頼・届出待ち」
B12: 4 | C12: 案内通知詳細 | D12: 依頼届出リンク | E12: 画面遷移 | F12: 顧客従業員 | G12: 依頼届出のステータスが「依頼・届出中」
B13: 5 | C13: 案内通知詳細 | D13: 依頼届出リンク | E13: 画面遷移 | F13: 顧客従業員 | G13: 依頼届出のステータスが「受付済」「処理中」「完了」
B14: 6 | C14: 顧客従業員向け_依頼届出一覧 | D14: 行クリック | E14: 画面遷移 | F14: 顧客従業員 | G14: 依頼届出のステータスが「依頼・届出待ち」
B15: 7 | C15: 顧客従業員向け_依頼届出一覧 | D15: 行クリック | E15: 画面遷移 | F15: 顧客従業員 | G15: 依頼届出のステータスが「依頼・届出中」
B16: 8 | C16: 顧客従業員向け_依頼届出一覧 | D16: 行クリック | E16: 画面遷移 | F16: 顧客従業員 | G16: 依頼届出のステータスが「受付済」「処理中」「完了」

Sheet 画面レイアウト_雇保給付金申請_高年齢_画面
A5: ◆初期表示時画面
A6: 【スマートフォン以外画面】 | BD6: 【スマートフォン画面】

Sheet ★画面項目定義_雇保給付金申請_高年齢
A5: No. | B5: 項目名 | C5: 項目ID(種別ID除く) | D5: 種類 | E5: 処理概要 | F5: ヒント文言 | G5: ラベルID | H5: 属性 | I5: 桁数 | J5: フォーマット | K5: 初期値 （新規登録時） | L5: 入力チェック | O5: 文字の配置 | P5: ページング | Q5: データベース | S5: 備考
L6: 必須 | M6: フォーマットチェック | N6: 入力制約 | Q6: テーブル名 | R6: テーブル項目名
A7: =ROW()-6 -> 1 | B7: 戻る | F7: ー | J7: ー | K7: ー | L7: ー | M7: ー | N7: ー
A8: =ROW()-6 -> 2 | B8: 依頼届出共通表示エリア | E8: ー | F8: ー | J8: ー | K8: ー | L8: ー | M8: ー | N8: ー | S8: 【基本設計書】画面設計_依頼届出共通 参照
A9: 5 | B9: 従業員情報エリア | F9: ー | J9: ー | K9: ー | L9: ー | M9: ー | N9: ー
A10: 6 | B10: 会社名 | E10: 従業員の所属する会社名を表示 | F10: ー | J10: ー | K10: ー | L10: ー | M10: ー | N10: ー
A11: 7 | B11: 従業員番号 | E11: 従業員番号を表示 | F11: ー | J11: ー | K11: ー | L11: ー | M11: ー | N11: ー
A12: 8 | B12: 従業員名 | E12: 従業員名を表示 | F12: ー | J12: 氏名_氏（漢字） ＋ ” ” ＋氏名_名（漢字） | K12: ー | L12: ー | M12: ー | N12: ー
A13: 9 | B13: 社会保険事業所コード | E13: 従業員の社労夢事業所コードを表示 (ユーザ属性マスタの社労夢用事業所番号） | F13: ー | J13: ー | K13: ー | L13: ー | M13: ー | N13: ー
A14: 10 | B14: マイナンバー有無エリア | F14: ー | J14: ー | K14: ー | L14: ー | M14: ー | N14: ー
A15: 11 | B15: マイナンバー | D15: ラジオボタン | F15: ー | J15: ー | K15: ー | L15: ー | M15: ー | N15: ー
A16: 12 | B16: 申請意思エリア | F16: ー | J16: ー | K16: ー | L16: ー | M16: ー | N16: ー
A17: 13 | B17: 給付金申請意思 | D17: ラジオボタン | F17: ー | J17: ー | K17: ー | L17: 〇 | M17: ー | N17: ー
A18: 14 | B18: 賃金登録同意 | D18: チェックボックス | F18: ー | J18: ー | K18: ー | L18: △ | M18: ー | N18: ー
A19: 15 | B19: 給付金口座情報エリア | F19: ー | J19: ー | K19: ー | L19: ー | M19: ー | N19: ー
A20: 16 | B20: 金融機関区分 | D20: ラジオボタン | L20: △ | M20: ー | N20: ー
A21: 17 | B21: 記号 | D21: テキストボックス | F21: 例）12345 | J21: 半角数字5桁 | L21: △ | M21: ○ | N21: ー | S21: 選択項目別表示制御参照
A22: 18 | B22: 番号 | D22: テキストボックス | F22: 例）12345678 | J22: 半角数字8桁 | L22: △ | M22: ○ | N22: ー | S22: 選択項目別表示制御参照
A23: 19 | B23: 金融機関コード | D23: テキストボックス | F23: 例）1234 | J23: 半角数字4桁 | L23: △ | M23: ○ | N23: ー | S23: 選択項目別表示制御参照
A24: 20 | B24: 金融機関名 | D24: テキストボックス | E24: ー | F24: 例）●●銀行 | J24: ー | L24: △ | M24: ー | N24: ー | S24: 選択項目別表示制御参照
A25: 21 | B25: 支店コード | D25: テキストボックス | F25: 例）123 | J25: 半角数字3桁 | L25: △ | M25: ○ | N25: ー | S25: 選択項目別表示制御参照
A26: 22 | B26: 本店・支店名 | D26: テキストボックス | E26: ー | F26: 例）●●支店 | J26: ー | L26: △ | M26: ー | N26: ー | S26: 選択項目別表示制御参照
A27: 23 | B27: 口座番号 | D27: テキストボックス | F27: 例）1234567 | J27: 半角数字7桁 | L27: △ | M27: ○ | N27: ー | S27: 選択項目別表示制御参照
A28: 24 | B28: 添付書類エリア | L28: ー | M28: ー | N28: ー
A29: 25 | B29: 添付書類 | D29: ファイル添付 | E29: ※モバイルの場合、スマホのカメラを起動し、撮影した画像を添付できること | L29: △ | M29: ー | N29: ー | S29: 選択項目別表示制御参照
A30: 26 | B30: 社内担当者使用欄エリア | L30: ー | M30: ー | N30: ー
A31: 27 | B31: 社内担当者使用欄 | D31: テキストエリア | L31: ー | M31: ー | N31: ー
A32: 28 | B32: 無効フラグ | D32: チェックボックス | L32: ー | M32: ー | N32: ー
A33: 29 | B33: 一時保存 | D33: ボタン | E33: 入力内容を一時保存 | L33: ー | M33: ー | N33: ー
A34: 30 | B34: 依頼・届出 | D34: ボタン | E34: 入力を確定して、ステータスを依頼・届出中に更新 | L34: ー | M34: ー | N34: ー
A35: 31 | B35: 引戻 | D35: ボタン | E35: 依頼届出中の案件を引戻して、ステータスを依頼・届出待ちに戻す | L35: ー | M35: ー | N35: ー
A36: 32 | B36: 登録 | D36: ボタン | E36: 入力内容を登録
A37: 33 | B37: 処理履歴 | D37: ボタン | E37: 処理履歴をポップアップ表示
A48: 【補足】

Sheet ★イベント概要
A5: No. | B5: 項目 | C5: イベント | D5: 処理概要
A7: =ROW()-6 -> 1 | B7: 画面 | C7: 初期表示 | D7: ①依頼届出番号で雇用保険_高年齢給付金申請を検索 データが存在する場合は画面項目にデータをセット ②呼び出し元画面、及び呼び出し条件により 「呼び出しパターン別画面表示制御」に従い、画面項目の表示制御を行う。 ③ログインユーザの権限により、「ステータス別制御」シートの「権限/ステータス別 更新制御」に従い画面の更新可否の制御、「ステータス別処理ボタン制御」に従いボタンの活性/非活性制御を行う。 ④「選択項目別表示制御」シートの「画面項目の表示制御」に従い、画面項目の表示制御を行う。
A8: =ROW()-6 -> 2 | B8: 申請意思 | C8: 選択 | D8: 「下記に同意し申請します」を選択した場合 金融機関区分を表示 「申請しません」を選択した場合 賃金登録同意を表示 給付金口座情報エリアの項目をすべてクリアし、非表示
A9: =ROW()-6 -> 3 | B9: 金融機関区分 | C9: 選択 | D9: 「ゆうちょ銀行」を選択した場合 記号‐番号を表示 マイナンバー＝なしの場合：添付ファイルを表示 金融機関コード、金融機関名、支店コード、本店・支店名、口座番号の入力値をクリア 「その他金融機関」を選択した場合 金融機関コード、金融機関名、支店コード、本店・支店名、口座番号を表示 マイナンバー＝なしの場合：添付ファイルを表示 記号‐番号の入力値をクリア
A10: =ROW()-6 -> 4 | B10: 一時保存 | C10: クリック | D10: 入力内容を一時保存（必須チェック不要） ステータス＝依頼届出待ち 処理履歴に追加
A11: =ROW()-6 -> 5 | B11: 依頼・届出 | C11: クリック | D11: 「選択項目別表示制御」シートの「入力チェック」に従い、入力チェックを行い、入力内容を登録 ステータス＝依頼届出中 処理履歴に追加
A12: =ROW()-6 -> 6 | B12: 引戻 | C12: クリック | D12: ステータスを依頼届出待ちに更新 処理履歴に追加
A13: =ROW()-6 -> 7 | B13: 登録 | C13: クリック | D13: 社内担当者使用欄、無効フラグを更新 処理履歴に追加
A14: =ROW()-6 -> 8 | B14: 処理履歴 | C14: クリック | D14: 処理履歴画面をポップアップで表示
A15: =ROW()-6 -> 9
A16: =ROW()-6 -> 10
A17: =ROW()-6 -> 11
A18: =ROW()-6 -> 12
A19: =ROW()-6 -> 13
A20: =ROW()-6 -> 14
A21: =ROW()-6 -> 15
A22: =ROW()-6 -> 16
A23: =ROW()-6 -> 17
A24: =ROW()-6 -> 18
A25: =ROW()-6 -> 19
A26: =ROW()-6 -> 20
... A41: =ROW()-6 -> 35
A42: 37
A43: 【補足】

Sheet ★呼び出しパターン別画面表示制御
A5: ■呼び出し元により以下の通り画面の表示制御行う
A7: No. | B7: 項目名 | C7: HROne/HRP担当者 | E7: 顧客従業員 | K7: 備考
C8: 案内通知 プレビュー | D8: 依頼・届出検索 | E8: 案内通知詳細 | H8: 依頼届出一覧
C9: ③ なし | D9: ④ なし | E9: ⑤ 依頼届出ステータス ＝「依頼・届出待ち」「一時保存」 | F9: ⑥ 依頼届出ステータス ＝「依頼・届出中」 | G9: ⑦ 依頼届出ステータス ＝「受付済」「処理中」「完了」 | H9: ⑧ 依頼届出ステータス ＝「依頼・届出待ち」「一時保存」 ※⑤と同じ | I9: ⑨ 依頼届出ステータス ＝「依頼・届出中」 ※⑥と同じ | J9: ⑩ 依頼届出ステータス ＝「受付済」「処理中」「完了」 ※⑦と同じ
A10: 1 | B10: 戻る | C10: 表示のみ | D10: 表示のみ | E10: 表示のみ | F10: 表示のみ | G10: 表示のみ | H10: 表示のみ | I10: 表示のみ | J10: 表示のみ
A11: 2 | B11: 依頼届出共通表示エリア | C11: 表示のみ | D11: 表示のみ | E11: 表示のみ | F11: 表示のみ | G11: 表示のみ | H11: 表示のみ | I11: 表示のみ | J11: 表示のみ | K11: 表示条件は 【基本設計書】従業員データ確認_画面設計 参照
A12: 5 | B12: 従業員情報エリア | C12: 表示のみ | D12: 表示のみ | E12: 非表示 | F12: 非表示 | G12: 非表示 | H12: 非表示 | I12: 非表示 | J12: 非表示
A13: 6 | B13: 会社名 | C13: 表示のみ | D13: 表示のみ | E13: 非表示 | F13: 非表示 | G13: 非表示 | H13: 非表示 | I13: 非表示 | J13: 非表示
A14: 7 | B14: 従業員番号 | C14: 表示のみ | D14: 表示のみ | E14: 非表示 | F14: 非表示 | G14: 非表示 | H14: 非表示 | I14: 非表示 | J14: 非表示
A15: 8 | B15: 従業員名 | C15: 表示のみ | D15: 表示のみ | E15: 非表示 | F15: 非表示 | G15: 非表示 | H15: 非表示 | I15: 非表示 | J15: 非表示
A16: 9 | B16: 社会保険事業所コード | C16: 表示のみ | D16: 表示のみ | E16: 非表示 | F16: 非表示 | G16: 非表示 | H16: 非表示 | I16: 非表示 | J16: 非表示
A17: 10 | B17: マイナンバー有無エリア | C17: 表示のみ | D17: 表示のみ | E17: 非表示 | F17: 非表示 | G17: 非表示 | H17: 非表示 | I17: 非表示 | J17: 非表示
A18: 11 | B18: マイナンバー | C18: 表示のみ | D18: 表示のみ | E18: 非表示 | F18: 非表示 | G18: 非表示 | H18: 非表示 | I18: 非表示 | J18: 非表示
A19: 12 | B19: 申請意思エリア | C19: 表示のみ | D19: 表示のみ | E19: 表示のみ | F19: 表示のみ | G19: 表示のみ | H19: 表示のみ | I19: 表示のみ | J19: 表示のみ | K19: 選択項目別表示制御参照
A20: 13 | B20: 給付金申請意思 | C20: 表示のみ | D20: 表示のみ | E20: 表示/入力可 | F20: 表示のみ | G20: 表示のみ | H20: 表示/入力可 | I20: 表示のみ | J20: 表示のみ | K20: 選択項目別表示制御参照
A21: 14 | B21: 賃金登録同意 | C21: 表示のみ | D21: 表示のみ | E21: 表示/入力可 | F21: 表示のみ | G21: 表示のみ | H21: 表示/入力可 | I21: 表示のみ | J21: 表示のみ | K21: 選択項目別表示制御参照
A22: 15 | B22: 給付金口座情報エリア | C22: 表示のみ | D22: 表示のみ | E22: 表示のみ | F22: 表示のみ | G22: 表示のみ | H22: 表示のみ | I22: 表示のみ | J22: 表示のみ | K22: 選択項目別表示制御参照
A23: 16 | B23: 金融機関区分 | C23: 表示のみ | D23: 表示のみ | E23: 表示/入力可 | F23: 表示のみ | G23: 表示のみ | H23: 表示/入力可 | I23: 表示のみ | J23: 表示のみ | K23: 選択項目別表示制御参照
A24: 17 | B24: 記号 | C24: 表示のみ | D24: 表示のみ | E24: 表示/入力可 | F24: 表示のみ | G24: 表示のみ | H24: 表示/入力可 | I24: 表示のみ | J24: 表示のみ | K24: 選択項目別表示制御参照
A25: 18 | B25: 番号 | C25: 表示のみ | D25: 表示のみ | E25: 表示/入力可 | F25: 表示のみ | G25: 表示のみ | H25: 表示/入力可 | I25: 表示のみ | J25: 表示のみ | K25: 選択項目別表示制御参照
A26: 19 | B26: 金融機関コード | C26: 表示のみ | D26: 表示のみ | E26: 表示/入力可 | F26: 表示のみ | G26: 表示のみ | H26: 表示/入力可 | I26: 表示のみ | J26: 表示のみ | K26: 選択項目別表示制御参照
A27: 20 | B27: 金融機関名 | C27: 表示のみ | D27: 表示のみ | E27: 表示/入力可 | F27: 表示のみ | G27: 表示のみ | H27: 表示/入力可 | I27: 表示のみ | J27: 表示のみ | K27: 選択項目別表示制御参照
A28: 21 | B28: 店舗コード | C28: 表示のみ | D28: 表示のみ | E28: 表示/入力可 | F28: 表示のみ | G28: 表示のみ | H28: 表示/入力可 | I28: 表示のみ | J28: 表示のみ | K28: 選択項目別表示制御参照
A29: 22 | B29: 店舗名 | C29: 表示のみ | D29: 表示のみ | E29: 表示/入力可 | F29: 表示のみ | G29: 表示のみ | H29: 表示/入力可 | I29: 表示のみ | J29: 表示のみ | K29: 選択項目別表示制御参照
A30: 23 | B30: 口座番号 | C30: 表示のみ | D30: 表示のみ | E30: 表示/入力可 | F30: 表示のみ | G30: 表示のみ | H30: 表示/入力可 | I30: 表示のみ | J30: 表示のみ | K30: 選択項目別表示制御参照
... A32: 25 | B32: 添付書類 | C32: 表示のみ | D32: 表示のみ | E32: 表示/入力可 | F32: 表示のみ | G32: 表示のみ | H32: 表示/入力可 | I32: 表示のみ | J32: 表示のみ | K32: 選択項目別表示制御参照
A33: 26 | B33: 社内担当者使用欄エリア | C33: 非表示 | D33: 表示のみ | E33: 非表示 | F33: 非表示 | G33: 非表示 | H33: 非表示 | I33: 非表示 | J33: 非表示
A34: 27 | B34: 社内担当者使用欄 | C34: 非表示 | D34: 表示/入力可 | E34: 非表示 | F34: 非表示 | G34: 非表示 | H34: 非表示 | I34: 非表示 | J34: 非表示
A35: 28 | B35: 無効 | C35: 非表示 | D35: 表示/入力可 | E35: 非表示 | F35: 非表示 | G35: 非表示 | H35: 非表示 | I35: 非表示 | J35: 非表示
A36: 29 | B36: 一時保存 | C36: 非表示 | D36: 非活性 | E36: 活性 | F36: 非活性 | G36: 非活性 | H36: 活性 | I36: 非活性 | J36: 非活性 | K36: ステータス別制御
A37: 30 | B37: 依頼・届出 | C37: 非表示 | D37: 非活性 | E37: 活性 | F37: 非活性 | G37: 非活性 | H37: 活性 | I37: 非活性 | J37: 非活性 | K37: ステータス別制御
A38: 31 | B38: 引戻 | C38: 非表示 | D38: 非活性 | E38: 非活性 | F38: 活性 | G38: 非活性 | H38: 非活性 | I38: 活性 | J38: 非活性 | K38: ステータス別制御
A39: 32 | B39: 登録 | C39: 非表示 | D39: 活性 | E39: 非表示 | F39: 非表示 | G39: 非表示 | H39: 非表示 | I39: 非表示 | J39: 非表示 | K39: ステータス別制御
A40: 33 | B40: 処理履歴 | C40: 非表示 | D40: 活性 | E40: 非表示 | F40: 非表示 | G40: 非表示 | H40: 非表示 | I40: 非表示 | J40: 非表示
A51: 【補足】

Sheet ★ステータス別制御 
A6: ■権限/ステータス別 更新制御
C7: HROne | G7: 顧客従業員
C8: 顧客権限あり | F8: 顧客権限なし
C9: 業務権限あり | E9: 業務権限なし
C10: 案内通知作成者 | D10: その他
A11: 1 | B11: 案内待ち | C11: 参照 無効フラグ 担当者使用欄入力 | D11: 参照 無効フラグ 担当者使用欄入力 | E11: ー | F11: ー | G11: ー
A12: 2 | B12: 依頼・届出待ち | E12: 参照のみ | F12: ー | G12: 参照/更新可
A13: 3 | B13: 一時保存 | C13: ー | D13: ー | E13: ー | F13: ー | G13: ー
A14: 4 | B14: 依頼・届出中 | C14: 参照 無効フラグ 担当者使用欄入力 | D14: 参照 無効フラグ 担当者使用欄入力 | E14: 参照のみ | F14: ー | G14: 参照/引戻可
A15: 5 | B15: 届出不要選択中 | C15: ー | D15: ー | E15: ー | F15: ー | G15: ー
A16: 6 | B16: 受付済 | C16: 参照 無効フラグ 担当者使用欄入力 | D16: 参照 無効フラグ 担当者使用欄入力 | E16: 参照のみ | F16: ー | G16: 参照のみ
A17: 7 | B17: 受付済（届出不要） | C17: ー | D17: ー | E17: ー | F17: ー | G17: ー
A18: 8 | B18: 処理中 | C18: 参照 無効フラグ 担当者使用欄入力 | D18: 参照 無効フラグ 担当者使用欄入力 | E18: 参照のみ | F18: ー | G18: 参照のみ
A19: 9 | B19: 完了 | F19: ー | H19: ※処理ボタンの表示もこの権限に準拠
A22: ■ステータス別処理ボタン制御
A24: HROne/HRP担当者の場合
C25: 処理履歴 | D25: 登録
A28: 1 | B28: 案内待ち | C28: 〇 | D28: 〇
A29: 2 | B29: 依頼・届出待ち | C29: 〇 | D29: 〇
A30: 3 | B30: 一時保存 | C30: ー | D30: ー
A31: 4 | B31: 依頼・届出中 | C31: 〇 | D31: 〇
A32: 5 | B32: 届出不要選択中 | C32: ー | D32: ー
A33: 6 | B33: 受付済 | C33: 〇 | D33: 〇
A34: 7 | B34: 受付済（届出不要） | C34: ー | D34: ー
A35: 8 | B35: 処理中 | C35: 〇 | D35: 〇
A36: 9 | B36: 完了 | C36: 〇 | D36: 〇
C38: 〇活性
C39: ー非活性
A41: 顧客従業員の場合
C42: 一時保存 | D42: 依頼・届出 | E42: 引戻
A45: 1 | B45: 案内待ち | C45: ー | D45: ー | E45: ー
A46: 2 | B46: 依頼・届出待ち | C46: 〇 | D46: 〇 | E46: ー
A47: 3 | B47: 一時保存 | C47: ー | D47: ー | E47: ー
A48: 4 | B48: 依頼・届出中 | C48: ー | D48: ー | E48: 〇
A49: 5 | B49: 届出不要選択中 | C49: ー | D49: ー | E49: ー
A50: 6 | B50: 受付済 | C50: ー | D50: ー | E50: ー
A51: 7 | B51: 受付済（届出不要） | C51: ー | D51: ー | E51: ー
A52: 8 | B52: 処理中 | C52: ー | D52: ー | E52: ー
A53: 9 | B53: 完了 | C53: ー | D53: ー | E53: ー
C55: 〇活性
...

Sheet 選択項目別表示制御
B6: ■画面項目の表示制御
B7: 表示１ | C7: マイナンバー | D7: あり | E7: 〇 | F7: 〇 | G7: 〇 | H7: 〇 | I7: 〇
D8: なし | J8: 〇 | K8: 〇 | L8: 〇 | M8: 〇 | N8: 〇
B9: 表示２ | C9: 申請意思 | D9: 未選択 | E9: 〇 | J9: 〇
D10: 申請します | F10: 〇 | G10: 〇 | H10: 〇 | K10: 〇 | L10: 〇 | M10: 〇
D11: 申請しません | I11: 〇 | N11: 〇
B12: 表示2-1 | C12: 賃金登録同意 | D12: 未選択 | E12: 非表示 | F12: 非表示 | G12: 非表示 | H12: 非表示 | I12: 〇 | J12: 非表示 | K12: 非表示 | L12: 非表示 | M12: 非表示 | N12: 〇 | O12: 表示２ 申請意思が、「申請します」の場合は非表示
B13: 表示３ | C13: 金融機関区分 | D13: 未選択 | E13: ー | F13: 〇 | I13: ー | J13: ー | K13: 〇 | N13: 非表示 | O13: 表示２ 申請意思が、「申請しません」の場合は非表示
D14: ゆうちょ銀行 | E14: 非表示 | G14: 〇 | I14: 非表示 | J14: 非表示 | L14: 〇 | N14: 非表示
D15: その他金融機関 | E15: 非表示 | H15: 〇 | I15: 非表示 | J15: 非表示 | M15: 〇 | N15: 非表示
B16: 表示４ | C16: 記号‐番号 | E16: 非表示 | F16: 非表示 | G16: 表示 | H16: 非表示 | I16: 非表示 | J16: 非表示 | K16: 非表示 | L16: 表示 | M16: 非表示 | N16: 非表示 | O16: 表示２ 申請意思が、「申請しません」の場合は非表示
C17: 金融機関コード | E17: 非表示 | F17: 非表示 | G17: 非表示 | H17: 表示 | I17: 非表示 | J17: 非表示 | K17: 非表示 | L17: 非表示 | M17: 表示 | N17: 非表示 | O17: 表示３ 金融機関区分によって表示制御
C18: 金融機関名 | E18: 非表示 | F18: 非表示 | G18: 非表示 | H18: 表示 | I18: 非表示 | J18: 非表示 | K18: 非表示 | L18: 非表示 | M18: 表示 | N18: 非表示
C19: 支店コード | E19: 非表示 | F19: 非表示 | G19: 非表示 | H19: 表示 | I19: 非表示 | J19: 非表示 | K19: 非表示 | L19: 非表示 | M19: 表示 | N19: 非表示
C20: 本店・支店名 | E20: 非表示 | F20: 非表示 | G20: 非表示 | H20: 表示 | I20: 非表示 | J20: 非表示 | K20: 非表示 | L20: 非表示 | M20: 表示 | N20: 非表示
C21: 口座番号 | E21: 非表示 | F21: 非表示 | G21: 非表示 | H21: 表示 | I21: 非表示 | J21: 非表示 | K21: 非表示 | L21: 非表示 | M21: 表示 | N21: 非表示
B22: 表示５ | C22: 添付書類 | E22: 非表示 | F22: 非表示 | G22: 非表示 | H22: 非表示 | I22: 非表示 | J22: 非表示 | K22: 表示 | L22: 表示 | M22: 表示 | N22: 表示 | O22: 表示1 マイナンバーが、「あり」の場合は非表示
B24: 条件によって非表示の場合は、データもすべてクリアする。
B25: ＜例＞
B26: 金融機関区分＝ゆうちょ銀行を選択し、記号‐番号入力後に、金融機関区分＝その他金融機関に変更した場合は、記号‐番号はクリアする
B28: ■入力チェック
B29: 項目 | C29: バリデーション | I29: 必須条件
C30: チェック | D30: エラーメッセージ | I30: チェック条件 | N30: エラーメッセージ
B31: 記号 | C31: 数字5桁 | D31: 記号は半角数字5桁で入力してください | I31: 金融機関区分＝ゆうちょ銀行の場合 | N31: 記号は入力必須項目です。
B32: 番号 | C32: 数字8桁 | D32: 番号は半角数字8桁で入力してください | I32: 金融機関区分＝ゆうちょ銀行の場合 | N32: 番号は入力必須項目です。
B33: 金融機関コード | C33: 数字4桁 | D33: 金融機関コードは半角数字4桁で入力してください | I33: 金融機関区分＝その他金融機関の場合 | N33: 金融機関コードは入力必須項目です。
B34: 支店コード | C34: 数字3桁 | D34: 支店コードは半角数字3桁で入力してください | I34: 金融機関区分＝その他金融機関の場合 | N34: 支店コードは入力必須項目です。
B35: 口座番号 | C35: 数字7桁 | D35: 口座番号は半角数字7桁で入力してください | I35: 金融機関区分＝その他金融機関の場合 | N35: 口座番号は入力必須項目です。
B36: 添付ファイル | C36: 共通チェック | D36: ※共通のエラー | I36: マイナンバー＝なしの場合 | N36: 【添付ファイル名】は添付必須です。

Sheet 参考
B2: 雇用保険：高年齢給付金開始手続
AL3: ★説明
B5: yyyy/mm/dd（aaa）までに届出してください | AE5: 依頼・届出待ち | AL5: 提出期限：
AM6: HRPからの案内で入力した期限を表示
C8: 会社名 | AL8: 従業員情報：
AM9: HRO・HRP担当者がこの画面を見る場合は表示
C10: 従業員番号 | AM10: 従業員様画面では非表示
C12: 従業員名
C16: 給付金の申請意思 | H16: （必須） | K16: 〇下記に同意、給付金を申請します | T16: 〇申請しません | AL16: 《高年齢給付金の申請を行わない方》：
AM17: 「申請意思＝申請しません」の場合のみ編集可・必須
D18: ・ | E18: 給付金申請に必要な手続きを行います
D19: ・ | E19: 転籍となった場合は、転籍先の会社にて引き続き給付金申請を行います
C22: 《高年齢給付金の申請を行わない方》
D23: 給付金の申請を行わない場合も、賃金登録は行う必要があります。
D24: □ | E24: 賃金登録を行うことに同意します
B28: 給付金振込先口座情報 | AL28: 給付金振込先口座情報：
AM29: 下記の条件に当てはまる場合に表示。
C30: 金融機関区分 | G30: （必須） | I30: 〇 | J30: ゆうちょ銀行 | O30: 〇 | P30: その他金融機関 | AM30: （条件）
AM31: 「給付金の申請意思＝申請します」
C32: 《ゆうちょ銀行の場合》
D34: 記号－番号（5桁－8桁） | J34: 12345 | N34: － | O34: 12345678
C37: 《その他金融機関の場合》
AL38: 口座情報：
D39: 金融機関コード（4桁） | J39: 0000 | AM39: 金融機関区分に応じて、その他情報の編集可否を制御
AM40: 金融機関区分 | AS40: 編集可項目
D41: 金融機関名 | AM41: ゆうちょ銀行 | AS41: 「記号－番号」のみ
AM42: その他金融機関 | AS42: 「記号－番号」以外
D43: 店舗コード（3桁） | J43: 000
D45: 本店・支店名
D47: 口座番号（7桁） | J47: 0123456 | R47: ※6桁の場合は頭に「0」をつけてください。
AL51: 添付書類：
B52: 添付書類 | AM52: 下記の条件に当てはまる場合に、以下の項目を表示。
AM53: （条件）
C54: （必須）運転免許証・パスポート・住民票の写し（マイナンバー記載なし）のいずれか1点 | AF54: ？ | AM54: HRPからの案内に持たせた「MN有無＝無」
C55: ※住民票の場合、3か月以内に発行されたもの
C56: 添付ファイル | AL56: ？ | AM56: ：
AM57: クリックすると詳細の説明を表示する
AL60: 依頼・届出：
AM61: 下記の場合はエラーチェック。同意のチェックONを促す。
AM62: 「申請意思＝申請しません」かつ「賃金登録の同意＝チェックなし」
...

Sheet 設定
A1: 有効/無効 | B1: BIS作成種類 | C1: [申請]処理対象者 | D1: [承認]処理対象者 | E1: [動的承認/確認/横配置/縦配置]処理対象者 | F1: ノード種別
A2: 有効 | B2: BAM | C2: 指定なし | D2: 指定なし | E2: 指定なし | F2: 開始
A3: 無効 | B3: WF | C3: ユーザ | D3: ユーザ | E3: ユーザ | F3: 終了
C4: 組織 | D4: 組織 | E4: 組織 | F4: 申請
C5: ロール | D5: ロール | E5: ロール | F5: 依頼
C6: パブリックグループ | D6: パブリックグループ | E6: パブリックグループ | F6: 承認
C7: 役職 | D7: 役職 | E7: 役職 | F7: 動的承認
C8: 役割 | D8: 役割 | E8: 役割 | F8: システム
C9: 組織＋役職 | D9: 組織＋役職 | E9: 組織＋役職 | F9: 確認
C10: パブリックグループ＋役割 | D10: パブリックグループ＋役割 | E10: パブリックグループ＋役割 | F10: 同期開始
C11: 組織＋ロール | D11: 組織＋ロール | E11: 組織＋ロール | F11: 同期終了
C12: パブリックグループ＋ロール | D12: パブリックグループ＋ロール | E12: パブリックグループ＋ロール | F12: 分岐開始
C13: 組織とその上位組織全て | D13: 申請/処理開始者 | E13: 組織とその上位組織全て | F13: 分岐終了
C14: 組織とその上位組織全て＋役職 | D14: 申請/処理開始者の所属組織 | E14: 組織とその上位組織全て＋役職 | F14: 横配置
C15: 組織とその上位組織全て＋ロール | D15: 申請/処理開始者の所属組織＋役職 | E15: 組織とその上位組織全て＋ロール | F15: 縦配置
... C18: 組織とその下位組織全て＋ロール | D18: 申請/処理開始者の上位組織＋役職 | E18: 組織とその下位組織全て＋ロール | F18: テンプレート終了
D19: 申請/処理開始者の上位組織＋ロール | F19: コメント
D20: 申請/処理開始者の上位組織全て | F20: スイムレーン
D21: 申請/処理開始者の上位組織全て＋役職
D22: 申請/処理開始者の上位組織全て＋ロール
D23: 申請/処理開始者の下位組織
D24: 申請/処理開始者の下位組織＋役職
D25: 申請/処理開始者の下位組織＋ロール
D26: 申請/処理開始者の下位組織全て
D27: 申請/処理開始者の下位組織全て＋役職
D28: 申請/処理開始者の下位組織全て＋ロール
D29: 組織とその上位組織全て
D30: 組織とその上位組織全て＋役職
D31: 組織とその上位組織全て＋ロール
D32: 組織とその下位組織全て
... D34: 組織とその下位組織全て＋ロール
